package com.boltcraft.basic;

import java.util.Random;

import net.minecraft.block.Block;
import net.minecraft.block.material.Material;
import net.minecraft.init.Blocks;
import net.minecraft.world.World;
import net.minecraft.world.gen.feature.WorldGenerator;

public class BoltStructureSmallCastle extends WorldGenerator
{
	protected Block[] GetValidSpawnBlocks()
	{
		return new Block[]
		{
			Blocks.grass,
			Blocks.dirt,
			Blocks.stone,
		};
	}

	public boolean LocationIsValidSpawn(World world, int x, int y, int z)
	{
		int distanceToAir = 0;
		Block checkBlock = world.getBlock(x, y, z);

		while (checkBlock != Blocks.air)
		{
			distanceToAir++;
			checkBlock = world.getBlock(x, y + distanceToAir, z);
		}

		if (distanceToAir > 1)
		{
			return false;
		}

		y += distanceToAir - 1;

		Block block = world.getBlock(x, y, z);
		Block blockAbove = world.getBlock(x, y + 1, z);
		Block blockBelow = world.getBlock(x, y - 1, z);

		for (Block i : GetValidSpawnBlocks())
		{
			if (blockAbove != Blocks.air)
			{
				return false;
			}
			if (block == i)
			{
				return true;
			}
			else if (block == Blocks.snow_layer && blockBelow == i)
			{
				return true;
			}
			else if (block.getMaterial() == Material.plants && blockBelow == i)
			{
				return true;
			}
		}
		return false;
	}

	public boolean generate(World world, Random rand, int x, int y, int z)
	{
		int i = rand.nextInt(1);

		if(i == 0)
		{
		    generate_r0(world, rand, x, y, z);
		}

       return true;

	}

	public boolean generate_r0(World world, Random rand, int x, int y, int z)
	{
		if(!LocationIsValidSpawn(world, x, y, z) || !LocationIsValidSpawn(world, x + 22, y, z) || !LocationIsValidSpawn(world, x + 22, y, z + 17) || !LocationIsValidSpawn(world, x, y, z + 17))
		{
			return false;
		}

		world.setBlock(x + 0, y + 0, z + 0, Blocks.planks, 0, 3);
		world.setBlock(x + 1, y + 0, z + 0, Blocks.planks, 0, 3);
		world.setBlock(x + 2, y + 0, z + 0, Blocks.planks, 0, 3);
		world.setBlock(x + 3, y + 0, z + 0, Blocks.planks, 0, 3);
		world.setBlock(x + 4, y + 0, z + 0, Blocks.planks, 0, 3);
		world.setBlock(x + 5, y + 0, z + 0, Blocks.planks, 0, 3);
		world.setBlock(x + 6, y + 0, z + 0, Blocks.planks, 0, 3);
		world.setBlock(x + 7, y + 0, z + 0, Blocks.planks, 0, 3);
		world.setBlock(x + 8, y + 0, z + 0, Blocks.planks, 0, 3);
		world.setBlock(x + 9, y + 0, z + 0, Blocks.planks, 0, 3);
		world.setBlock(x + 10, y + 0, z + 0, Blocks.planks, 0, 3);
		world.setBlock(x + 11, y + 0, z + 0, Blocks.planks, 0, 3);
		world.setBlock(x + 12, y + 0, z + 0, Blocks.planks, 0, 3);
		world.setBlock(x + 13, y + 0, z + 0, Blocks.planks, 0, 3);
		world.setBlock(x + 14, y + 0, z + 0, Blocks.planks, 0, 3);
		world.setBlock(x + 15, y + 0, z + 0, Blocks.planks, 0, 3);
		world.setBlock(x + 16, y + 0, z + 0, Blocks.planks, 0, 3);
		world.setBlock(x + 17, y + 0, z + 0, Blocks.planks, 0, 3);
		world.setBlock(x + 18, y + 0, z + 0, Blocks.planks, 0, 3);
		world.setBlock(x + 19, y + 0, z + 0, Blocks.planks, 0, 3);
		world.setBlock(x + 20, y + 0, z + 0, Blocks.planks, 0, 3);
		world.setBlock(x + 21, y + 0, z + 0, Blocks.planks, 0, 3);
		world.setBlock(x + 22, y + 0, z + 0, Blocks.planks, 0, 3);
		world.setBlock(x + 0, y + 0, z + 1, Blocks.planks, 0, 3);
		world.setBlock(x + 1, y + 0, z + 1, Blocks.planks, 0, 3);
		world.setBlock(x + 2, y + 0, z + 1, Blocks.planks, 0, 3);
		world.setBlock(x + 3, y + 0, z + 1, Blocks.planks, 0, 3);
		world.setBlock(x + 4, y + 0, z + 1, Blocks.planks, 0, 3);
		world.setBlock(x + 5, y + 0, z + 1, Blocks.planks, 0, 3);
		world.setBlock(x + 6, y + 0, z + 1, Blocks.planks, 0, 3);
		world.setBlock(x + 7, y + 0, z + 1, Blocks.planks, 0, 3);
		world.setBlock(x + 8, y + 0, z + 1, Blocks.planks, 0, 3);
		world.setBlock(x + 9, y + 0, z + 1, Blocks.planks, 0, 3);
		world.setBlock(x + 10, y + 0, z + 1, Blocks.planks, 0, 3);
		world.setBlock(x + 11, y + 0, z + 1, Blocks.planks, 0, 3);
		world.setBlock(x + 12, y + 0, z + 1, Blocks.planks, 0, 3);
		world.setBlock(x + 13, y + 0, z + 1, Blocks.planks, 0, 3);
		world.setBlock(x + 14, y + 0, z + 1, Blocks.planks, 0, 3);
		world.setBlock(x + 15, y + 0, z + 1, Blocks.planks, 0, 3);
		world.setBlock(x + 16, y + 0, z + 1, Blocks.planks, 0, 3);
		world.setBlock(x + 17, y + 0, z + 1, Blocks.planks, 0, 3);
		world.setBlock(x + 18, y + 0, z + 1, Blocks.planks, 0, 3);
		world.setBlock(x + 19, y + 0, z + 1, Blocks.planks, 0, 3);
		world.setBlock(x + 20, y + 0, z + 1, Blocks.planks, 0, 3);
		world.setBlock(x + 21, y + 0, z + 1, Blocks.planks, 0, 3);
		world.setBlock(x + 22, y + 0, z + 1, Blocks.planks, 0, 3);
		world.setBlock(x + 0, y + 0, z + 2, Blocks.planks, 0, 3);
		world.setBlock(x + 1, y + 0, z + 2, Blocks.planks, 0, 3);
		world.setBlock(x + 2, y + 0, z + 2, Blocks.planks, 0, 3);
		world.setBlock(x + 3, y + 0, z + 2, Blocks.planks, 0, 3);
		world.setBlock(x + 4, y + 0, z + 2, Blocks.planks, 0, 3);
		world.setBlock(x + 5, y + 0, z + 2, Blocks.planks, 0, 3);
		world.setBlock(x + 6, y + 0, z + 2, Blocks.planks, 0, 3);
		world.setBlock(x + 7, y + 0, z + 2, Blocks.planks, 0, 3);
		world.setBlock(x + 8, y + 0, z + 2, Blocks.planks, 0, 3);
		world.setBlock(x + 9, y + 0, z + 2, Blocks.planks, 0, 3);
		world.setBlock(x + 10, y + 0, z + 2, Blocks.planks, 0, 3);
		world.setBlock(x + 11, y + 0, z + 2, Blocks.planks, 0, 3);
		world.setBlock(x + 12, y + 0, z + 2, Blocks.planks, 0, 3);
		world.setBlock(x + 13, y + 0, z + 2, Blocks.planks, 0, 3);
		world.setBlock(x + 14, y + 0, z + 2, Blocks.planks, 0, 3);
		world.setBlock(x + 15, y + 0, z + 2, Blocks.planks, 0, 3);
		world.setBlock(x + 16, y + 0, z + 2, Blocks.planks, 0, 3);
		world.setBlock(x + 17, y + 0, z + 2, Blocks.planks, 0, 3);
		world.setBlock(x + 18, y + 0, z + 2, Blocks.planks, 0, 3);
		world.setBlock(x + 19, y + 0, z + 2, Blocks.planks, 0, 3);
		world.setBlock(x + 20, y + 0, z + 2, Blocks.planks, 0, 3);
		world.setBlock(x + 21, y + 0, z + 2, Blocks.planks, 0, 3);
		world.setBlock(x + 22, y + 0, z + 2, Blocks.planks, 0, 3);
		world.setBlock(x + 0, y + 0, z + 3, Blocks.planks, 0, 3);
		world.setBlock(x + 1, y + 0, z + 3, Blocks.planks, 0, 3);
		world.setBlock(x + 2, y + 0, z + 3, Blocks.planks, 0, 3);
		world.setBlock(x + 3, y + 0, z + 3, Blocks.planks, 0, 3);
		world.setBlock(x + 4, y + 0, z + 3, Blocks.planks, 0, 3);
		world.setBlock(x + 5, y + 0, z + 3, Blocks.planks, 0, 3);
		world.setBlock(x + 6, y + 0, z + 3, Blocks.planks, 0, 3);
		world.setBlock(x + 7, y + 0, z + 3, Blocks.planks, 0, 3);
		world.setBlock(x + 8, y + 0, z + 3, Blocks.planks, 0, 3);
		world.setBlock(x + 9, y + 0, z + 3, Blocks.planks, 0, 3);
		world.setBlock(x + 10, y + 0, z + 3, Blocks.planks, 0, 3);
		world.setBlock(x + 11, y + 0, z + 3, Blocks.planks, 0, 3);
		world.setBlock(x + 12, y + 0, z + 3, Blocks.planks, 0, 3);
		world.setBlock(x + 13, y + 0, z + 3, Blocks.planks, 0, 3);
		world.setBlock(x + 14, y + 0, z + 3, Blocks.planks, 0, 3);
		world.setBlock(x + 15, y + 0, z + 3, Blocks.planks, 0, 3);
		world.setBlock(x + 16, y + 0, z + 3, Blocks.planks, 0, 3);
		world.setBlock(x + 17, y + 0, z + 3, Blocks.planks, 0, 3);
		world.setBlock(x + 18, y + 0, z + 3, Blocks.planks, 0, 3);
		world.setBlock(x + 19, y + 0, z + 3, Blocks.planks, 0, 3);
		world.setBlock(x + 20, y + 0, z + 3, Blocks.planks, 0, 3);
		world.setBlock(x + 21, y + 0, z + 3, Blocks.planks, 0, 3);
		world.setBlock(x + 22, y + 0, z + 3, Blocks.planks, 0, 3);
		world.setBlock(x + 0, y + 0, z + 4, Blocks.planks, 0, 3);
		world.setBlock(x + 1, y + 0, z + 4, Blocks.planks, 0, 3);
		world.setBlock(x + 2, y + 0, z + 4, Blocks.planks, 0, 3);
		world.setBlock(x + 3, y + 0, z + 4, Blocks.planks, 0, 3);
		world.setBlock(x + 4, y + 0, z + 4, Blocks.planks, 0, 3);
		world.setBlock(x + 5, y + 0, z + 4, Blocks.planks, 0, 3);
		world.setBlock(x + 6, y + 0, z + 4, Blocks.planks, 0, 3);
		world.setBlock(x + 7, y + 0, z + 4, Blocks.planks, 0, 3);
		world.setBlock(x + 8, y + 0, z + 4, Blocks.planks, 0, 3);
		world.setBlock(x + 9, y + 0, z + 4, Blocks.planks, 0, 3);
		world.setBlock(x + 10, y + 0, z + 4, Blocks.planks, 0, 3);
		world.setBlock(x + 11, y + 0, z + 4, Blocks.planks, 0, 3);
		world.setBlock(x + 12, y + 0, z + 4, Blocks.planks, 0, 3);
		world.setBlock(x + 13, y + 0, z + 4, Blocks.planks, 0, 3);
		world.setBlock(x + 14, y + 0, z + 4, Blocks.planks, 0, 3);
		world.setBlock(x + 15, y + 0, z + 4, Blocks.planks, 0, 3);
		world.setBlock(x + 16, y + 0, z + 4, Blocks.planks, 0, 3);
		world.setBlock(x + 17, y + 0, z + 4, Blocks.planks, 0, 3);
		world.setBlock(x + 18, y + 0, z + 4, Blocks.planks, 0, 3);
		world.setBlock(x + 19, y + 0, z + 4, Blocks.planks, 0, 3);
		world.setBlock(x + 20, y + 0, z + 4, Blocks.planks, 0, 3);
		world.setBlock(x + 21, y + 0, z + 4, Blocks.planks, 0, 3);
		world.setBlock(x + 22, y + 0, z + 4, Blocks.planks, 0, 3);
		world.setBlock(x + 0, y + 0, z + 5, Blocks.planks, 0, 3);
		world.setBlock(x + 1, y + 0, z + 5, Blocks.planks, 0, 3);
		world.setBlock(x + 2, y + 0, z + 5, Blocks.planks, 0, 3);
		world.setBlock(x + 3, y + 0, z + 5, Blocks.planks, 0, 3);
		world.setBlock(x + 4, y + 0, z + 5, Blocks.planks, 0, 3);
		world.setBlock(x + 5, y + 0, z + 5, Blocks.planks, 0, 3);
		world.setBlock(x + 6, y + 0, z + 5, Blocks.planks, 0, 3);
		world.setBlock(x + 7, y + 0, z + 5, Blocks.planks, 0, 3);
		world.setBlock(x + 8, y + 0, z + 5, Blocks.planks, 0, 3);
		world.setBlock(x + 9, y + 0, z + 5, Blocks.planks, 0, 3);
		world.setBlock(x + 10, y + 0, z + 5, Blocks.planks, 0, 3);
		world.setBlock(x + 11, y + 0, z + 5, Blocks.planks, 0, 3);
		world.setBlock(x + 12, y + 0, z + 5, Blocks.planks, 0, 3);
		world.setBlock(x + 13, y + 0, z + 5, Blocks.planks, 0, 3);
		world.setBlock(x + 14, y + 0, z + 5, Blocks.planks, 0, 3);
		world.setBlock(x + 15, y + 0, z + 5, Blocks.planks, 0, 3);
		world.setBlock(x + 16, y + 0, z + 5, Blocks.planks, 0, 3);
		world.setBlock(x + 17, y + 0, z + 5, Blocks.planks, 0, 3);
		world.setBlock(x + 18, y + 0, z + 5, Blocks.planks, 0, 3);
		world.setBlock(x + 19, y + 0, z + 5, Blocks.planks, 0, 3);
		world.setBlock(x + 20, y + 0, z + 5, Blocks.planks, 0, 3);
		world.setBlock(x + 21, y + 0, z + 5, Blocks.planks, 0, 3);
		world.setBlock(x + 22, y + 0, z + 5, Blocks.planks, 0, 3);
		world.setBlock(x + 0, y + 0, z + 6, Blocks.planks, 0, 3);
		world.setBlock(x + 1, y + 0, z + 6, Blocks.planks, 0, 3);
		world.setBlock(x + 2, y + 0, z + 6, Blocks.planks, 0, 3);
		world.setBlock(x + 3, y + 0, z + 6, Blocks.planks, 0, 3);
		world.setBlock(x + 4, y + 0, z + 6, Blocks.planks, 0, 3);
		world.setBlock(x + 5, y + 0, z + 6, Blocks.planks, 0, 3);
		world.setBlock(x + 6, y + 0, z + 6, Blocks.planks, 0, 3);
		world.setBlock(x + 7, y + 0, z + 6, Blocks.planks, 0, 3);
		world.setBlock(x + 8, y + 0, z + 6, Blocks.planks, 0, 3);
		world.setBlock(x + 9, y + 0, z + 6, Blocks.planks, 0, 3);
		world.setBlock(x + 10, y + 0, z + 6, Blocks.planks, 0, 3);
		world.setBlock(x + 11, y + 0, z + 6, Blocks.planks, 0, 3);
		world.setBlock(x + 12, y + 0, z + 6, Blocks.planks, 0, 3);
		world.setBlock(x + 13, y + 0, z + 6, Blocks.planks, 0, 3);
		world.setBlock(x + 14, y + 0, z + 6, Blocks.planks, 0, 3);
		world.setBlock(x + 15, y + 0, z + 6, Blocks.planks, 0, 3);
		world.setBlock(x + 16, y + 0, z + 6, Blocks.planks, 0, 3);
		world.setBlock(x + 17, y + 0, z + 6, Blocks.planks, 0, 3);
		world.setBlock(x + 18, y + 0, z + 6, Blocks.planks, 0, 3);
		world.setBlock(x + 19, y + 0, z + 6, Blocks.planks, 0, 3);
		world.setBlock(x + 20, y + 0, z + 6, Blocks.planks, 0, 3);
		world.setBlock(x + 21, y + 0, z + 6, Blocks.planks, 0, 3);
		world.setBlock(x + 22, y + 0, z + 6, Blocks.planks, 0, 3);
		world.setBlock(x + 0, y + 0, z + 7, Blocks.planks, 0, 3);
		world.setBlock(x + 1, y + 0, z + 7, Blocks.planks, 0, 3);
		world.setBlock(x + 2, y + 0, z + 7, Blocks.planks, 0, 3);
		world.setBlock(x + 3, y + 0, z + 7, Blocks.planks, 0, 3);
		world.setBlock(x + 4, y + 0, z + 7, Blocks.planks, 0, 3);
		world.setBlock(x + 5, y + 0, z + 7, Blocks.planks, 0, 3);
		world.setBlock(x + 6, y + 0, z + 7, Blocks.planks, 0, 3);
		world.setBlock(x + 7, y + 0, z + 7, Blocks.planks, 0, 3);
		world.setBlock(x + 8, y + 0, z + 7, Blocks.planks, 0, 3);
		world.setBlock(x + 9, y + 0, z + 7, Blocks.planks, 0, 3);
		world.setBlock(x + 10, y + 0, z + 7, Blocks.planks, 0, 3);
		world.setBlock(x + 11, y + 0, z + 7, Blocks.planks, 0, 3);
		world.setBlock(x + 12, y + 0, z + 7, Blocks.planks, 0, 3);
		world.setBlock(x + 13, y + 0, z + 7, Blocks.planks, 0, 3);
		world.setBlock(x + 14, y + 0, z + 7, Blocks.planks, 0, 3);
		world.setBlock(x + 15, y + 0, z + 7, Blocks.planks, 0, 3);
		world.setBlock(x + 16, y + 0, z + 7, Blocks.planks, 0, 3);
		world.setBlock(x + 17, y + 0, z + 7, Blocks.planks, 0, 3);
		world.setBlock(x + 18, y + 0, z + 7, Blocks.planks, 0, 3);
		world.setBlock(x + 19, y + 0, z + 7, Blocks.planks, 0, 3);
		world.setBlock(x + 20, y + 0, z + 7, Blocks.planks, 0, 3);
		world.setBlock(x + 21, y + 0, z + 7, Blocks.planks, 0, 3);
		world.setBlock(x + 22, y + 0, z + 7, Blocks.planks, 0, 3);
		world.setBlock(x + 0, y + 0, z + 8, Blocks.planks, 0, 3);
		world.setBlock(x + 1, y + 0, z + 8, Blocks.planks, 0, 3);
		world.setBlock(x + 2, y + 0, z + 8, Blocks.planks, 0, 3);
		world.setBlock(x + 3, y + 0, z + 8, Blocks.planks, 0, 3);
		world.setBlock(x + 4, y + 0, z + 8, Blocks.planks, 0, 3);
		world.setBlock(x + 5, y + 0, z + 8, Blocks.planks, 0, 3);
		world.setBlock(x + 6, y + 0, z + 8, Blocks.planks, 0, 3);
		world.setBlock(x + 7, y + 0, z + 8, Blocks.planks, 0, 3);
		world.setBlock(x + 8, y + 0, z + 8, Blocks.planks, 0, 3);
		world.setBlock(x + 9, y + 0, z + 8, Blocks.planks, 0, 3);
		world.setBlock(x + 10, y + 0, z + 8, Blocks.planks, 0, 3);
		world.setBlock(x + 11, y + 0, z + 8, Blocks.planks, 0, 3);
		world.setBlock(x + 12, y + 0, z + 8, Blocks.planks, 0, 3);
		world.setBlock(x + 13, y + 0, z + 8, Blocks.planks, 0, 3);
		world.setBlock(x + 14, y + 0, z + 8, Blocks.planks, 0, 3);
		world.setBlock(x + 15, y + 0, z + 8, Blocks.planks, 0, 3);
		world.setBlock(x + 16, y + 0, z + 8, Blocks.planks, 0, 3);
		world.setBlock(x + 17, y + 0, z + 8, Blocks.planks, 0, 3);
		world.setBlock(x + 18, y + 0, z + 8, Blocks.planks, 0, 3);
		world.setBlock(x + 19, y + 0, z + 8, Blocks.planks, 0, 3);
		world.setBlock(x + 20, y + 0, z + 8, Blocks.planks, 0, 3);
		world.setBlock(x + 21, y + 0, z + 8, Blocks.planks, 0, 3);
		world.setBlock(x + 22, y + 0, z + 8, Blocks.planks, 0, 3);
		world.setBlock(x + 0, y + 0, z + 9, Blocks.planks, 0, 3);
		world.setBlock(x + 1, y + 0, z + 9, Blocks.planks, 0, 3);
		world.setBlock(x + 2, y + 0, z + 9, Blocks.planks, 0, 3);
		world.setBlock(x + 3, y + 0, z + 9, Blocks.planks, 0, 3);
		world.setBlock(x + 4, y + 0, z + 9, Blocks.planks, 0, 3);
		world.setBlock(x + 5, y + 0, z + 9, Blocks.planks, 0, 3);
		world.setBlock(x + 6, y + 0, z + 9, Blocks.planks, 0, 3);
		world.setBlock(x + 7, y + 0, z + 9, Blocks.planks, 0, 3);
		world.setBlock(x + 8, y + 0, z + 9, Blocks.planks, 0, 3);
		world.setBlock(x + 9, y + 0, z + 9, Blocks.planks, 0, 3);
		world.setBlock(x + 10, y + 0, z + 9, Blocks.planks, 0, 3);
		world.setBlock(x + 11, y + 0, z + 9, Blocks.planks, 0, 3);
		world.setBlock(x + 12, y + 0, z + 9, Blocks.planks, 0, 3);
		world.setBlock(x + 13, y + 0, z + 9, Blocks.planks, 0, 3);
		world.setBlock(x + 14, y + 0, z + 9, Blocks.planks, 0, 3);
		world.setBlock(x + 15, y + 0, z + 9, Blocks.planks, 0, 3);
		world.setBlock(x + 16, y + 0, z + 9, Blocks.planks, 0, 3);
		world.setBlock(x + 17, y + 0, z + 9, Blocks.planks, 0, 3);
		world.setBlock(x + 18, y + 0, z + 9, Blocks.planks, 0, 3);
		world.setBlock(x + 19, y + 0, z + 9, Blocks.planks, 0, 3);
		world.setBlock(x + 20, y + 0, z + 9, Blocks.planks, 0, 3);
		world.setBlock(x + 21, y + 0, z + 9, Blocks.planks, 0, 3);
		world.setBlock(x + 22, y + 0, z + 9, Blocks.planks, 0, 3);
		world.setBlock(x + 0, y + 0, z + 10, Blocks.planks, 0, 3);
		world.setBlock(x + 1, y + 0, z + 10, Blocks.planks, 0, 3);
		world.setBlock(x + 2, y + 0, z + 10, Blocks.planks, 0, 3);
		world.setBlock(x + 3, y + 0, z + 10, Blocks.planks, 0, 3);
		world.setBlock(x + 4, y + 0, z + 10, Blocks.planks, 0, 3);
		world.setBlock(x + 5, y + 0, z + 10, Blocks.planks, 0, 3);
		world.setBlock(x + 6, y + 0, z + 10, Blocks.planks, 0, 3);
		world.setBlock(x + 7, y + 0, z + 10, Blocks.planks, 0, 3);
		world.setBlock(x + 8, y + 0, z + 10, Blocks.planks, 0, 3);
		world.setBlock(x + 9, y + 0, z + 10, Blocks.planks, 0, 3);
		world.setBlock(x + 10, y + 0, z + 10, Blocks.planks, 0, 3);
		world.setBlock(x + 11, y + 0, z + 10, Blocks.planks, 0, 3);
		world.setBlock(x + 12, y + 0, z + 10, Blocks.planks, 0, 3);
		world.setBlock(x + 13, y + 0, z + 10, Blocks.planks, 0, 3);
		world.setBlock(x + 14, y + 0, z + 10, Blocks.planks, 0, 3);
		world.setBlock(x + 15, y + 0, z + 10, Blocks.planks, 0, 3);
		world.setBlock(x + 16, y + 0, z + 10, Blocks.planks, 0, 3);
		world.setBlock(x + 17, y + 0, z + 10, Blocks.planks, 0, 3);
		world.setBlock(x + 18, y + 0, z + 10, Blocks.planks, 0, 3);
		world.setBlock(x + 19, y + 0, z + 10, Blocks.planks, 0, 3);
		world.setBlock(x + 20, y + 0, z + 10, Blocks.planks, 0, 3);
		world.setBlock(x + 21, y + 0, z + 10, Blocks.planks, 0, 3);
		world.setBlock(x + 22, y + 0, z + 10, Blocks.planks, 0, 3);
		world.setBlock(x + 0, y + 0, z + 11, Blocks.planks, 0, 3);
		world.setBlock(x + 1, y + 0, z + 11, Blocks.planks, 0, 3);
		world.setBlock(x + 2, y + 0, z + 11, Blocks.planks, 0, 3);
		world.setBlock(x + 3, y + 0, z + 11, Blocks.planks, 0, 3);
		world.setBlock(x + 4, y + 0, z + 11, Blocks.planks, 0, 3);
		world.setBlock(x + 5, y + 0, z + 11, Blocks.planks, 0, 3);
		world.setBlock(x + 6, y + 0, z + 11, Blocks.planks, 0, 3);
		world.setBlock(x + 7, y + 0, z + 11, Blocks.planks, 0, 3);
		world.setBlock(x + 8, y + 0, z + 11, Blocks.planks, 0, 3);
		world.setBlock(x + 9, y + 0, z + 11, Blocks.planks, 0, 3);
		world.setBlock(x + 10, y + 0, z + 11, Blocks.planks, 0, 3);
		world.setBlock(x + 11, y + 0, z + 11, Blocks.planks, 0, 3);
		world.setBlock(x + 12, y + 0, z + 11, Blocks.planks, 0, 3);
		world.setBlock(x + 13, y + 0, z + 11, Blocks.planks, 0, 3);
		world.setBlock(x + 14, y + 0, z + 11, Blocks.planks, 0, 3);
		world.setBlock(x + 15, y + 0, z + 11, Blocks.planks, 0, 3);
		world.setBlock(x + 16, y + 0, z + 11, Blocks.planks, 0, 3);
		world.setBlock(x + 17, y + 0, z + 11, Blocks.planks, 0, 3);
		world.setBlock(x + 18, y + 0, z + 11, Blocks.planks, 0, 3);
		world.setBlock(x + 19, y + 0, z + 11, Blocks.planks, 0, 3);
		world.setBlock(x + 20, y + 0, z + 11, Blocks.planks, 0, 3);
		world.setBlock(x + 21, y + 0, z + 11, Blocks.planks, 0, 3);
		world.setBlock(x + 22, y + 0, z + 11, Blocks.planks, 0, 3);
		world.setBlock(x + 0, y + 0, z + 12, Blocks.planks, 0, 3);
		world.setBlock(x + 1, y + 0, z + 12, Blocks.planks, 0, 3);
		world.setBlock(x + 2, y + 0, z + 12, Blocks.planks, 0, 3);
		world.setBlock(x + 3, y + 0, z + 12, Blocks.planks, 0, 3);
		world.setBlock(x + 4, y + 0, z + 12, Blocks.planks, 0, 3);
		world.setBlock(x + 5, y + 0, z + 12, Blocks.planks, 0, 3);
		world.setBlock(x + 6, y + 0, z + 12, Blocks.planks, 0, 3);
		world.setBlock(x + 7, y + 0, z + 12, Blocks.planks, 0, 3);
		world.setBlock(x + 8, y + 0, z + 12, Blocks.planks, 0, 3);
		world.setBlock(x + 9, y + 0, z + 12, Blocks.planks, 0, 3);
		world.setBlock(x + 10, y + 0, z + 12, Blocks.planks, 0, 3);
		world.setBlock(x + 11, y + 0, z + 12, Blocks.planks, 0, 3);
		world.setBlock(x + 12, y + 0, z + 12, Blocks.planks, 0, 3);
		world.setBlock(x + 13, y + 0, z + 12, Blocks.planks, 0, 3);
		world.setBlock(x + 14, y + 0, z + 12, Blocks.planks, 0, 3);
		world.setBlock(x + 15, y + 0, z + 12, Blocks.planks, 0, 3);
		world.setBlock(x + 16, y + 0, z + 12, Blocks.planks, 0, 3);
		world.setBlock(x + 17, y + 0, z + 12, Blocks.planks, 0, 3);
		world.setBlock(x + 18, y + 0, z + 12, Blocks.planks, 0, 3);
		world.setBlock(x + 19, y + 0, z + 12, Blocks.planks, 0, 3);
		world.setBlock(x + 20, y + 0, z + 12, Blocks.planks, 0, 3);
		world.setBlock(x + 21, y + 0, z + 12, Blocks.planks, 0, 3);
		world.setBlock(x + 22, y + 0, z + 12, Blocks.planks, 0, 3);
		world.setBlock(x + 0, y + 0, z + 13, Blocks.planks, 0, 3);
		world.setBlock(x + 1, y + 0, z + 13, Blocks.planks, 0, 3);
		world.setBlock(x + 2, y + 0, z + 13, Blocks.planks, 0, 3);
		world.setBlock(x + 3, y + 0, z + 13, Blocks.planks, 0, 3);
		world.setBlock(x + 4, y + 0, z + 13, Blocks.planks, 0, 3);
		world.setBlock(x + 5, y + 0, z + 13, Blocks.planks, 0, 3);
		world.setBlock(x + 6, y + 0, z + 13, Blocks.planks, 0, 3);
		world.setBlock(x + 7, y + 0, z + 13, Blocks.planks, 0, 3);
		world.setBlock(x + 8, y + 0, z + 13, Blocks.planks, 0, 3);
		world.setBlock(x + 9, y + 0, z + 13, Blocks.planks, 0, 3);
		world.setBlock(x + 10, y + 0, z + 13, Blocks.planks, 0, 3);
		world.setBlock(x + 11, y + 0, z + 13, Blocks.planks, 0, 3);
		world.setBlock(x + 12, y + 0, z + 13, Blocks.planks, 0, 3);
		world.setBlock(x + 13, y + 0, z + 13, Blocks.planks, 0, 3);
		world.setBlock(x + 14, y + 0, z + 13, Blocks.planks, 0, 3);
		world.setBlock(x + 15, y + 0, z + 13, Blocks.planks, 0, 3);
		world.setBlock(x + 16, y + 0, z + 13, Blocks.planks, 0, 3);
		world.setBlock(x + 17, y + 0, z + 13, Blocks.planks, 0, 3);
		world.setBlock(x + 18, y + 0, z + 13, Blocks.planks, 0, 3);
		world.setBlock(x + 19, y + 0, z + 13, Blocks.planks, 0, 3);
		world.setBlock(x + 20, y + 0, z + 13, Blocks.planks, 0, 3);
		world.setBlock(x + 21, y + 0, z + 13, Blocks.planks, 0, 3);
		world.setBlock(x + 22, y + 0, z + 13, Blocks.planks, 0, 3);
		world.setBlock(x + 0, y + 0, z + 14, Blocks.planks, 0, 3);
		world.setBlock(x + 1, y + 0, z + 14, Blocks.planks, 0, 3);
		world.setBlock(x + 2, y + 0, z + 14, Blocks.planks, 0, 3);
		world.setBlock(x + 3, y + 0, z + 14, Blocks.planks, 0, 3);
		world.setBlock(x + 4, y + 0, z + 14, Blocks.planks, 0, 3);
		world.setBlock(x + 5, y + 0, z + 14, Blocks.planks, 0, 3);
		world.setBlock(x + 6, y + 0, z + 14, Blocks.planks, 0, 3);
		world.setBlock(x + 7, y + 0, z + 14, Blocks.planks, 0, 3);
		world.setBlock(x + 8, y + 0, z + 14, Blocks.planks, 0, 3);
		world.setBlock(x + 9, y + 0, z + 14, Blocks.planks, 0, 3);
		world.setBlock(x + 10, y + 0, z + 14, Blocks.planks, 0, 3);
		world.setBlock(x + 11, y + 0, z + 14, Blocks.planks, 0, 3);
		world.setBlock(x + 12, y + 0, z + 14, Blocks.planks, 0, 3);
		world.setBlock(x + 13, y + 0, z + 14, Blocks.planks, 0, 3);
		world.setBlock(x + 14, y + 0, z + 14, Blocks.planks, 0, 3);
		world.setBlock(x + 15, y + 0, z + 14, Blocks.planks, 0, 3);
		world.setBlock(x + 16, y + 0, z + 14, Blocks.planks, 0, 3);
		world.setBlock(x + 17, y + 0, z + 14, Blocks.planks, 0, 3);
		world.setBlock(x + 18, y + 0, z + 14, Blocks.planks, 0, 3);
		world.setBlock(x + 19, y + 0, z + 14, Blocks.planks, 0, 3);
		world.setBlock(x + 20, y + 0, z + 14, Blocks.planks, 0, 3);
		world.setBlock(x + 21, y + 0, z + 14, Blocks.planks, 0, 3);
		world.setBlock(x + 22, y + 0, z + 14, Blocks.planks, 0, 3);
		world.setBlock(x + 0, y + 0, z + 15, Blocks.planks, 0, 3);
		world.setBlock(x + 1, y + 0, z + 15, Blocks.planks, 0, 3);
		world.setBlock(x + 2, y + 0, z + 15, Blocks.planks, 0, 3);
		world.setBlock(x + 3, y + 0, z + 15, Blocks.planks, 0, 3);
		world.setBlock(x + 4, y + 0, z + 15, Blocks.planks, 0, 3);
		world.setBlock(x + 5, y + 0, z + 15, Blocks.planks, 0, 3);
		world.setBlock(x + 6, y + 0, z + 15, Blocks.planks, 0, 3);
		world.setBlock(x + 7, y + 0, z + 15, Blocks.planks, 0, 3);
		world.setBlock(x + 8, y + 0, z + 15, Blocks.planks, 0, 3);
		world.setBlock(x + 9, y + 0, z + 15, Blocks.planks, 0, 3);
		world.setBlock(x + 10, y + 0, z + 15, Blocks.planks, 0, 3);
		world.setBlock(x + 11, y + 0, z + 15, Blocks.planks, 0, 3);
		world.setBlock(x + 12, y + 0, z + 15, Blocks.planks, 0, 3);
		world.setBlock(x + 13, y + 0, z + 15, Blocks.planks, 0, 3);
		world.setBlock(x + 14, y + 0, z + 15, Blocks.planks, 0, 3);
		world.setBlock(x + 15, y + 0, z + 15, Blocks.planks, 0, 3);
		world.setBlock(x + 16, y + 0, z + 15, Blocks.planks, 0, 3);
		world.setBlock(x + 17, y + 0, z + 15, Blocks.planks, 0, 3);
		world.setBlock(x + 18, y + 0, z + 15, Blocks.planks, 0, 3);
		world.setBlock(x + 19, y + 0, z + 15, Blocks.planks, 0, 3);
		world.setBlock(x + 20, y + 0, z + 15, Blocks.planks, 0, 3);
		world.setBlock(x + 21, y + 0, z + 15, Blocks.planks, 0, 3);
		world.setBlock(x + 22, y + 0, z + 15, Blocks.planks, 0, 3);
		world.setBlock(x + 0, y + 0, z + 16, Blocks.planks, 0, 3);
		world.setBlock(x + 1, y + 0, z + 16, Blocks.planks, 0, 3);
		world.setBlock(x + 2, y + 0, z + 16, Blocks.planks, 0, 3);
		world.setBlock(x + 3, y + 0, z + 16, Blocks.planks, 0, 3);
		world.setBlock(x + 4, y + 0, z + 16, Blocks.planks, 0, 3);
		world.setBlock(x + 5, y + 0, z + 16, Blocks.planks, 0, 3);
		world.setBlock(x + 6, y + 0, z + 16, Blocks.planks, 0, 3);
		world.setBlock(x + 7, y + 0, z + 16, Blocks.planks, 0, 3);
		world.setBlock(x + 8, y + 0, z + 16, Blocks.planks, 0, 3);
		world.setBlock(x + 9, y + 0, z + 16, Blocks.planks, 0, 3);
		world.setBlock(x + 10, y + 0, z + 16, Blocks.planks, 0, 3);
		world.setBlock(x + 11, y + 0, z + 16, Blocks.planks, 0, 3);
		world.setBlock(x + 12, y + 0, z + 16, Blocks.planks, 0, 3);
		world.setBlock(x + 13, y + 0, z + 16, Blocks.planks, 0, 3);
		world.setBlock(x + 14, y + 0, z + 16, Blocks.planks, 0, 3);
		world.setBlock(x + 15, y + 0, z + 16, Blocks.planks, 0, 3);
		world.setBlock(x + 16, y + 0, z + 16, Blocks.planks, 0, 3);
		world.setBlock(x + 17, y + 0, z + 16, Blocks.planks, 0, 3);
		world.setBlock(x + 18, y + 0, z + 16, Blocks.planks, 0, 3);
		world.setBlock(x + 19, y + 0, z + 16, Blocks.planks, 0, 3);
		world.setBlock(x + 20, y + 0, z + 16, Blocks.planks, 0, 3);
		world.setBlock(x + 21, y + 0, z + 16, Blocks.planks, 0, 3);
		world.setBlock(x + 22, y + 0, z + 16, Blocks.planks, 0, 3);
		world.setBlock(x + 0, y + 0, z + 17, Blocks.planks, 0, 3);
		world.setBlock(x + 1, y + 0, z + 17, Blocks.planks, 0, 3);
		world.setBlock(x + 2, y + 0, z + 17, Blocks.planks, 0, 3);
		world.setBlock(x + 3, y + 0, z + 17, Blocks.planks, 0, 3);
		world.setBlock(x + 4, y + 0, z + 17, Blocks.planks, 0, 3);
		world.setBlock(x + 5, y + 0, z + 17, Blocks.planks, 0, 3);
		world.setBlock(x + 6, y + 0, z + 17, Blocks.planks, 0, 3);
		world.setBlock(x + 7, y + 0, z + 17, Blocks.planks, 0, 3);
		world.setBlock(x + 8, y + 0, z + 17, Blocks.planks, 0, 3);
		world.setBlock(x + 9, y + 0, z + 17, Blocks.planks, 0, 3);
		world.setBlock(x + 10, y + 0, z + 17, Blocks.planks, 0, 3);
		world.setBlock(x + 11, y + 0, z + 17, Blocks.planks, 0, 3);
		world.setBlock(x + 12, y + 0, z + 17, Blocks.planks, 0, 3);
		world.setBlock(x + 13, y + 0, z + 17, Blocks.planks, 0, 3);
		world.setBlock(x + 14, y + 0, z + 17, Blocks.planks, 0, 3);
		world.setBlock(x + 15, y + 0, z + 17, Blocks.planks, 0, 3);
		world.setBlock(x + 16, y + 0, z + 17, Blocks.planks, 0, 3);
		world.setBlock(x + 17, y + 0, z + 17, Blocks.planks, 0, 3);
		world.setBlock(x + 18, y + 0, z + 17, Blocks.planks, 0, 3);
		world.setBlock(x + 19, y + 0, z + 17, Blocks.planks, 0, 3);
		world.setBlock(x + 20, y + 0, z + 17, Blocks.planks, 0, 3);
		world.setBlock(x + 21, y + 0, z + 17, Blocks.planks, 0, 3);
		world.setBlock(x + 22, y + 0, z + 17, Blocks.planks, 0, 3);
		world.setBlock(x + 0, y + 1, z + 0, Blocks.stone, 0, 3);
		world.setBlock(x + 1, y + 1, z + 0, Blocks.stone, 0, 3);
		world.setBlock(x + 2, y + 1, z + 0, Blocks.stone, 0, 3);
		world.setBlock(x + 3, y + 1, z + 0, Blocks.stone, 0, 3);
		world.setBlock(x + 4, y + 1, z + 0, Blocks.stone, 0, 3);
		world.setBlock(x + 5, y + 1, z + 0, Blocks.stone, 0, 3);
		world.setBlock(x + 6, y + 1, z + 0, Blocks.stone, 0, 3);
		world.setBlock(x + 7, y + 1, z + 0, Blocks.stone, 0, 3);
		world.setBlock(x + 8, y + 1, z + 0, Blocks.stone, 0, 3);
		world.setBlock(x + 9, y + 1, z + 0, Blocks.air, 0, 3);
		world.setBlock(x + 10, y + 1, z + 0, Blocks.air, 0, 3);
		world.setBlock(x + 11, y + 1, z + 0, Blocks.double_stone_slab, 0, 3);
		world.setBlock(x + 12, y + 1, z + 0, Blocks.air, 0, 3);
		world.setBlock(x + 13, y + 1, z + 0, Blocks.air, 0, 3);
		world.setBlock(x + 14, y + 1, z + 0, Blocks.air, 0, 3);
		world.setBlock(x + 15, y + 1, z + 0, Blocks.air, 0, 3);
		world.setBlock(x + 16, y + 1, z + 0, Blocks.air, 0, 3);
		world.setBlock(x + 17, y + 1, z + 0, Blocks.air, 0, 3);
		world.setBlock(x + 18, y + 1, z + 0, Blocks.air, 0, 3);
		world.setBlock(x + 19, y + 1, z + 0, Blocks.air, 0, 3);
		world.setBlock(x + 20, y + 1, z + 0, Blocks.air, 0, 3);
		world.setBlock(x + 21, y + 1, z + 0, Blocks.air, 0, 3);
		world.setBlock(x + 22, y + 1, z + 0, Blocks.air, 0, 3);
		world.setBlock(x + 0, y + 1, z + 1, Blocks.stone, 0, 3);
		world.setBlock(x + 1, y + 1, z + 1, Blocks.air, 0, 3);
		world.setBlock(x + 2, y + 1, z + 1, Blocks.air, 0, 3);
		world.setBlock(x + 3, y + 1, z + 1, Blocks.air, 0, 3);
		world.setBlock(x + 4, y + 1, z + 1, Blocks.air, 0, 3);
		world.setBlock(x + 5, y + 1, z + 1, Blocks.air, 0, 3);
		world.setBlock(x + 6, y + 1, z + 1, Blocks.air, 0, 3);
		world.setBlock(x + 7, y + 1, z + 1, Blocks.air, 0, 3);
		world.setBlock(x + 8, y + 1, z + 1, Blocks.stone, 0, 3);
		world.setBlock(x + 9, y + 1, z + 1, Blocks.air, 0, 3);
		world.setBlock(x + 10, y + 1, z + 1, Blocks.air, 0, 3);
		world.setBlock(x + 11, y + 1, z + 1, Blocks.double_stone_slab, 0, 3);
		world.setBlock(x + 12, y + 1, z + 1, Blocks.air, 0, 3);
		world.setBlock(x + 13, y + 1, z + 1, Blocks.air, 0, 3);
		world.setBlock(x + 14, y + 1, z + 1, Blocks.air, 0, 3);
		world.setBlock(x + 15, y + 1, z + 1, Blocks.air, 0, 3);
		world.setBlock(x + 16, y + 1, z + 1, Blocks.air, 0, 3);
		world.setBlock(x + 17, y + 1, z + 1, Blocks.air, 0, 3);
		world.setBlock(x + 18, y + 1, z + 1, Blocks.air, 0, 3);
		world.setBlock(x + 19, y + 1, z + 1, Blocks.air, 0, 3);
		world.setBlock(x + 20, y + 1, z + 1, Blocks.air, 0, 3);
		world.setBlock(x + 21, y + 1, z + 1, Blocks.air, 0, 3);
		world.setBlock(x + 22, y + 1, z + 1, Blocks.air, 0, 3);
		world.setBlock(x + 0, y + 1, z + 2, Blocks.stone, 0, 3);
		world.setBlock(x + 1, y + 1, z + 2, Blocks.air, 0, 3);
		world.setBlock(x + 2, y + 1, z + 2, Blocks.air, 0, 3);
		world.setBlock(x + 3, y + 1, z + 2, Blocks.air, 0, 3);
		world.setBlock(x + 4, y + 1, z + 2, Blocks.air, 0, 3);
		world.setBlock(x + 5, y + 1, z + 2, Blocks.air, 0, 3);
		world.setBlock(x + 6, y + 1, z + 2, Blocks.air, 0, 3);
		world.setBlock(x + 7, y + 1, z + 2, Blocks.air, 0, 3);
		world.setBlock(x + 8, y + 1, z + 2, Blocks.stone, 0, 3);
		world.setBlock(x + 9, y + 1, z + 2, Blocks.air, 0, 3);
		world.setBlock(x + 10, y + 1, z + 2, Blocks.air, 0, 3);
		world.setBlock(x + 11, y + 1, z + 2, Blocks.double_stone_slab, 0, 3);
		world.setBlock(x + 12, y + 1, z + 2, Blocks.double_stone_slab, 0, 3);
		world.setBlock(x + 13, y + 1, z + 2, Blocks.double_stone_slab, 0, 3);
		world.setBlock(x + 14, y + 1, z + 2, Blocks.double_stone_slab, 0, 3);
		world.setBlock(x + 15, y + 1, z + 2, Blocks.double_stone_slab, 0, 3);
		world.setBlock(x + 16, y + 1, z + 2, Blocks.double_stone_slab, 0, 3);
		world.setBlock(x + 17, y + 1, z + 2, Blocks.double_stone_slab, 0, 3);
		world.setBlock(x + 18, y + 1, z + 2, Blocks.double_stone_slab, 0, 3);
		world.setBlock(x + 19, y + 1, z + 2, Blocks.double_stone_slab, 0, 3);
		world.setBlock(x + 20, y + 1, z + 2, Blocks.air, 0, 3);
		world.setBlock(x + 21, y + 1, z + 2, Blocks.air, 0, 3);
		world.setBlock(x + 22, y + 1, z + 2, Blocks.air, 0, 3);
		world.setBlock(x + 0, y + 1, z + 3, Blocks.stone, 0, 3);
		world.setBlock(x + 1, y + 1, z + 3, Blocks.air, 0, 3);
		world.setBlock(x + 2, y + 1, z + 3, Blocks.air, 0, 3);
		world.setBlock(x + 3, y + 1, z + 3, Blocks.air, 0, 3);
		world.setBlock(x + 4, y + 1, z + 3, Blocks.air, 0, 3);
		world.setBlock(x + 5, y + 1, z + 3, Blocks.air, 0, 3);
		world.setBlock(x + 6, y + 1, z + 3, Blocks.air, 0, 3);
		world.setBlock(x + 7, y + 1, z + 3, Blocks.air, 0, 3);
		world.setBlock(x + 8, y + 1, z + 3, Blocks.stone, 0, 3);
		world.setBlock(x + 9, y + 1, z + 3, Blocks.air, 0, 3);
		world.setBlock(x + 10, y + 1, z + 3, Blocks.air, 0, 3);
		world.setBlock(x + 11, y + 1, z + 3, Blocks.air, 0, 3);
		world.setBlock(x + 12, y + 1, z + 3, Blocks.air, 0, 3);
		world.setBlock(x + 13, y + 1, z + 3, Blocks.air, 0, 3);
		world.setBlock(x + 14, y + 1, z + 3, Blocks.air, 0, 3);
		world.setBlock(x + 15, y + 1, z + 3, Blocks.air, 0, 3);
		world.setBlock(x + 16, y + 1, z + 3, Blocks.air, 0, 3);
		world.setBlock(x + 17, y + 1, z + 3, Blocks.air, 0, 3);
		world.setBlock(x + 18, y + 1, z + 3, Blocks.air, 0, 3);
		world.setBlock(x + 19, y + 1, z + 3, Blocks.air, 0, 3);
		world.setBlock(x + 20, y + 1, z + 3, Blocks.air, 0, 3);
		world.setBlock(x + 21, y + 1, z + 3, Blocks.air, 0, 3);
		world.setBlock(x + 22, y + 1, z + 3, Blocks.air, 0, 3);
		world.setBlock(x + 0, y + 1, z + 4, Blocks.stone, 0, 3);
		world.setBlock(x + 1, y + 1, z + 4, Blocks.air, 0, 3);
		world.setBlock(x + 2, y + 1, z + 4, Blocks.air, 0, 3);
		world.setBlock(x + 3, y + 1, z + 4, Blocks.air, 0, 3);
		world.setBlock(x + 4, y + 1, z + 4, Blocks.stone_slab, 0, 3);
		world.setBlock(x + 5, y + 1, z + 4, Blocks.air, 0, 3);
		world.setBlock(x + 6, y + 1, z + 4, Blocks.air, 0, 3);
		world.setBlock(x + 7, y + 1, z + 4, Blocks.air, 0, 3);
		world.setBlock(x + 8, y + 1, z + 4, Blocks.wooden_door, 5, 3);
		world.setBlock(x + 9, y + 1, z + 4, Blocks.air, 0, 3);
		world.setBlock(x + 10, y + 1, z + 4, Blocks.air, 0, 3);
		world.setBlock(x + 11, y + 1, z + 4, Blocks.air, 0, 3);
		world.setBlock(x + 12, y + 1, z + 4, Blocks.air, 0, 3);
		world.setBlock(x + 13, y + 1, z + 4, Blocks.air, 0, 3);
		world.setBlock(x + 14, y + 1, z + 4, Blocks.air, 0, 3);
		world.setBlock(x + 15, y + 1, z + 4, Blocks.air, 0, 3);
		world.setBlock(x + 16, y + 1, z + 4, Blocks.air, 0, 3);
		world.setBlock(x + 17, y + 1, z + 4, Blocks.air, 0, 3);
		world.setBlock(x + 18, y + 1, z + 4, Blocks.air, 0, 3);
		world.setBlock(x + 19, y + 1, z + 4, Blocks.air, 0, 3);
		world.setBlock(x + 20, y + 1, z + 4, Blocks.air, 0, 3);
		world.setBlock(x + 21, y + 1, z + 4, Blocks.air, 0, 3);
		world.setBlock(x + 22, y + 1, z + 4, Blocks.air, 0, 3);
		world.setBlock(x + 0, y + 1, z + 5, Blocks.stone, 0, 3);
		world.setBlock(x + 1, y + 1, z + 5, Blocks.air, 0, 3);
		world.setBlock(x + 2, y + 1, z + 5, Blocks.air, 0, 3);
		world.setBlock(x + 3, y + 1, z + 5, Blocks.log, 0, 3);
		world.setBlock(x + 4, y + 1, z + 5, Blocks.log, 0, 3);
		world.setBlock(x + 5, y + 1, z + 5, Blocks.log, 0, 3);
		world.setBlock(x + 6, y + 1, z + 5, Blocks.air, 0, 3);
		world.setBlock(x + 7, y + 1, z + 5, Blocks.stone_pressure_plate, 0, 3);
		world.setBlock(x + 8, y + 1, z + 5, Blocks.wooden_door, 2, 3);
		world.setBlock(x + 9, y + 1, z + 5, Blocks.stone_pressure_plate, 0, 3);
		world.setBlock(x + 10, y + 1, z + 5, Blocks.air, 0, 3);
		world.setBlock(x + 11, y + 1, z + 5, Blocks.air, 0, 3);
		world.setBlock(x + 12, y + 1, z + 5, Blocks.air, 0, 3);
		world.setBlock(x + 13, y + 1, z + 5, Blocks.air, 0, 3);
		world.setBlock(x + 14, y + 1, z + 5, Blocks.air, 0, 3);
		world.setBlock(x + 15, y + 1, z + 5, Blocks.air, 0, 3);
		world.setBlock(x + 16, y + 1, z + 5, Blocks.air, 0, 3);
		world.setBlock(x + 17, y + 1, z + 5, Blocks.air, 0, 3);
		world.setBlock(x + 18, y + 1, z + 5, Blocks.air, 0, 3);
		world.setBlock(x + 19, y + 1, z + 5, Blocks.air, 0, 3);
		world.setBlock(x + 20, y + 1, z + 5, Blocks.stone_pressure_plate, 0, 3);
		world.setBlock(x + 21, y + 1, z + 5, Blocks.air, 0, 3);
		world.setBlock(x + 22, y + 1, z + 5, Blocks.air, 0, 3);
		world.setBlock(x + 0, y + 1, z + 6, Blocks.stone, 0, 3);
		world.setBlock(x + 1, y + 1, z + 6, Blocks.air, 0, 3);
		world.setBlock(x + 2, y + 1, z + 6, Blocks.stone_slab, 0, 3);
		world.setBlock(x + 3, y + 1, z + 6, Blocks.log, 0, 3);
		world.setBlock(x + 4, y + 1, z + 6, Blocks.log, 0, 3);
		world.setBlock(x + 5, y + 1, z + 6, Blocks.log, 0, 3);
		world.setBlock(x + 6, y + 1, z + 6, Blocks.stone_slab, 0, 3);
		world.setBlock(x + 7, y + 1, z + 6, Blocks.air, 0, 3);
		world.setBlock(x + 8, y + 1, z + 6, Blocks.stone, 0, 3);
		world.setBlock(x + 9, y + 1, z + 6, Blocks.air, 0, 3);
		world.setBlock(x + 10, y + 1, z + 6, Blocks.air, 0, 3);
		world.setBlock(x + 11, y + 1, z + 6, Blocks.air, 0, 3);
		world.setBlock(x + 12, y + 1, z + 6, Blocks.air, 0, 3);
		world.setBlock(x + 13, y + 1, z + 6, Blocks.air, 0, 3);
		world.setBlock(x + 14, y + 1, z + 6, Blocks.air, 0, 3);
		world.setBlock(x + 15, y + 1, z + 6, Blocks.air, 0, 3);
		world.setBlock(x + 16, y + 1, z + 6, Blocks.air, 0, 3);
		world.setBlock(x + 17, y + 1, z + 6, Blocks.stone, 0, 3);
		world.setBlock(x + 18, y + 1, z + 6, Blocks.stone, 0, 3);
		world.setBlock(x + 19, y + 1, z + 6, Blocks.wooden_door, 4, 3);
		world.setBlock(x + 20, y + 1, z + 6, Blocks.wooden_door, 1, 3);
		world.setBlock(x + 21, y + 1, z + 6, Blocks.stone, 0, 3);
		world.setBlock(x + 22, y + 1, z + 6, Blocks.stone, 0, 3);
		world.setBlock(x + 0, y + 1, z + 7, Blocks.stone, 0, 3);
		world.setBlock(x + 1, y + 1, z + 7, Blocks.air, 0, 3);
		world.setBlock(x + 2, y + 1, z + 7, Blocks.air, 0, 3);
		world.setBlock(x + 3, y + 1, z + 7, Blocks.log, 0, 3);
		world.setBlock(x + 4, y + 1, z + 7, Blocks.log, 0, 3);
		world.setBlock(x + 5, y + 1, z + 7, Blocks.log, 0, 3);
		world.setBlock(x + 6, y + 1, z + 7, Blocks.air, 0, 3);
		world.setBlock(x + 7, y + 1, z + 7, Blocks.air, 0, 3);
		world.setBlock(x + 8, y + 1, z + 7, Blocks.stone, 0, 3);
		world.setBlock(x + 9, y + 1, z + 7, Blocks.air, 0, 3);
		world.setBlock(x + 10, y + 1, z + 7, Blocks.air, 0, 3);
		world.setBlock(x + 11, y + 1, z + 7, Blocks.air, 0, 3);
		world.setBlock(x + 12, y + 1, z + 7, Blocks.air, 0, 3);
		world.setBlock(x + 13, y + 1, z + 7, Blocks.air, 0, 3);
		world.setBlock(x + 14, y + 1, z + 7, Blocks.air, 0, 3);
		world.setBlock(x + 15, y + 1, z + 7, Blocks.air, 0, 3);
		world.setBlock(x + 16, y + 1, z + 7, Blocks.air, 0, 3);
		world.setBlock(x + 17, y + 1, z + 7, Blocks.stone, 0, 3);
		world.setBlock(x + 18, y + 1, z + 7, Blocks.log, 0, 3);
		world.setBlock(x + 19, y + 1, z + 7, Blocks.air, 0, 3);
		world.setBlock(x + 20, y + 1, z + 7, Blocks.stone_pressure_plate, 0, 3);
		world.setBlock(x + 21, y + 1, z + 7, Blocks.log, 0, 3);
		world.setBlock(x + 22, y + 1, z + 7, Blocks.stone, 0, 3);
		world.setBlock(x + 0, y + 1, z + 8, Blocks.wooden_door, 0, 3);
		world.setBlock(x + 1, y + 1, z + 8, Blocks.stone_pressure_plate, 0, 3);
		world.setBlock(x + 2, y + 1, z + 8, Blocks.air, 0, 3);
		world.setBlock(x + 3, y + 1, z + 8, Blocks.air, 0, 3);
		world.setBlock(x + 4, y + 1, z + 8, Blocks.stone_slab, 0, 3);
		world.setBlock(x + 5, y + 1, z + 8, Blocks.air, 0, 3);
		world.setBlock(x + 6, y + 1, z + 8, Blocks.air, 0, 3);
		world.setBlock(x + 7, y + 1, z + 8, Blocks.air, 0, 3);
		world.setBlock(x + 8, y + 1, z + 8, Blocks.stone, 0, 3);
		world.setBlock(x + 9, y + 1, z + 8, Blocks.air, 0, 3);
		world.setBlock(x + 10, y + 1, z + 8, Blocks.air, 0, 3);
		world.setBlock(x + 11, y + 1, z + 8, Blocks.air, 0, 3);
		world.setBlock(x + 12, y + 1, z + 8, Blocks.air, 0, 3);
		world.setBlock(x + 13, y + 1, z + 8, Blocks.air, 0, 3);
		world.setBlock(x + 14, y + 1, z + 8, Blocks.air, 0, 3);
		world.setBlock(x + 15, y + 1, z + 8, Blocks.air, 0, 3);
		world.setBlock(x + 16, y + 1, z + 8, Blocks.air, 0, 3);
		world.setBlock(x + 17, y + 1, z + 8, Blocks.stone, 0, 3);
		world.setBlock(x + 18, y + 1, z + 8, Blocks.log, 0, 3);
		world.setBlock(x + 19, y + 1, z + 8, Blocks.air, 0, 3);
		world.setBlock(x + 20, y + 1, z + 8, Blocks.air, 0, 3);
		world.setBlock(x + 21, y + 1, z + 8, Blocks.log, 0, 3);
		world.setBlock(x + 22, y + 1, z + 8, Blocks.stone, 0, 3);
		world.setBlock(x + 0, y + 1, z + 9, Blocks.wooden_door, 7, 3);
		world.setBlock(x + 1, y + 1, z + 9, Blocks.air, 0, 3);
		world.setBlock(x + 2, y + 1, z + 9, Blocks.air, 0, 3);
		world.setBlock(x + 3, y + 1, z + 9, Blocks.air, 0, 3);
		world.setBlock(x + 4, y + 1, z + 9, Blocks.air, 0, 3);
		world.setBlock(x + 5, y + 1, z + 9, Blocks.air, 0, 3);
		world.setBlock(x + 6, y + 1, z + 9, Blocks.air, 0, 3);
		world.setBlock(x + 7, y + 1, z + 9, Blocks.air, 0, 3);
		world.setBlock(x + 8, y + 1, z + 9, Blocks.stone, 0, 3);
		world.setBlock(x + 9, y + 1, z + 9, Blocks.air, 0, 3);
		world.setBlock(x + 10, y + 1, z + 9, Blocks.air, 0, 3);
		world.setBlock(x + 11, y + 1, z + 9, Blocks.air, 0, 3);
		world.setBlock(x + 12, y + 1, z + 9, Blocks.air, 0, 3);
		world.setBlock(x + 13, y + 1, z + 9, Blocks.stone_pressure_plate, 0, 3);
		world.setBlock(x + 14, y + 1, z + 9, Blocks.air, 0, 3);
		world.setBlock(x + 15, y + 1, z + 9, Blocks.air, 0, 3);
		world.setBlock(x + 16, y + 1, z + 9, Blocks.air, 0, 3);
		world.setBlock(x + 17, y + 1, z + 9, Blocks.stone, 0, 3);
		world.setBlock(x + 18, y + 1, z + 9, Blocks.air, 0, 3);
		world.setBlock(x + 19, y + 1, z + 9, Blocks.air, 0, 3);
		world.setBlock(x + 20, y + 1, z + 9, Blocks.air, 0, 3);
		world.setBlock(x + 21, y + 1, z + 9, Blocks.air, 0, 3);
		world.setBlock(x + 22, y + 1, z + 9, Blocks.stone, 0, 3);
		world.setBlock(x + 0, y + 1, z + 10, Blocks.stone, 0, 3);
		world.setBlock(x + 1, y + 1, z + 10, Blocks.air, 0, 3);
		world.setBlock(x + 2, y + 1, z + 10, Blocks.air, 0, 3);
		world.setBlock(x + 3, y + 1, z + 10, Blocks.air, 0, 3);
		world.setBlock(x + 4, y + 1, z + 10, Blocks.air, 0, 3);
		world.setBlock(x + 5, y + 1, z + 10, Blocks.air, 0, 3);
		world.setBlock(x + 6, y + 1, z + 10, Blocks.air, 0, 3);
		world.setBlock(x + 7, y + 1, z + 10, Blocks.air, 0, 3);
		world.setBlock(x + 8, y + 1, z + 10, Blocks.stone, 0, 3);
		world.setBlock(x + 9, y + 1, z + 10, Blocks.stone, 0, 3);
		world.setBlock(x + 10, y + 1, z + 10, Blocks.stone, 0, 3);
		world.setBlock(x + 11, y + 1, z + 10, Blocks.stone, 0, 3);
		world.setBlock(x + 12, y + 1, z + 10, Blocks.wooden_door, 4, 3);
		world.setBlock(x + 13, y + 1, z + 10, Blocks.wooden_door, 1, 3);
		world.setBlock(x + 14, y + 1, z + 10, Blocks.stone, 0, 3);
		world.setBlock(x + 15, y + 1, z + 10, Blocks.stone, 0, 3);
		world.setBlock(x + 16, y + 1, z + 10, Blocks.stone, 0, 3);
		world.setBlock(x + 17, y + 1, z + 10, Blocks.stone, 0, 3);
		world.setBlock(x + 18, y + 1, z + 10, Blocks.air, 0, 3);
		world.setBlock(x + 19, y + 1, z + 10, Blocks.air, 0, 3);
		world.setBlock(x + 20, y + 1, z + 10, Blocks.air, 0, 3);
		world.setBlock(x + 21, y + 1, z + 10, Blocks.air, 0, 3);
		world.setBlock(x + 22, y + 1, z + 10, Blocks.stone, 0, 3);
		world.setBlock(x + 0, y + 1, z + 11, Blocks.stone, 0, 3);
		world.setBlock(x + 1, y + 1, z + 11, Blocks.air, 0, 3);
		world.setBlock(x + 2, y + 1, z + 11, Blocks.air, 0, 3);
		world.setBlock(x + 3, y + 1, z + 11, Blocks.air, 0, 3);
		world.setBlock(x + 4, y + 1, z + 11, Blocks.air, 0, 3);
		world.setBlock(x + 5, y + 1, z + 11, Blocks.air, 0, 3);
		world.setBlock(x + 6, y + 1, z + 11, Blocks.air, 0, 3);
		world.setBlock(x + 7, y + 1, z + 11, Blocks.air, 0, 3);
		world.setBlock(x + 8, y + 1, z + 11, Blocks.air, 0, 3);
		world.setBlock(x + 9, y + 1, z + 11, Blocks.air, 0, 3);
		world.setBlock(x + 10, y + 1, z + 11, Blocks.air, 0, 3);
		world.setBlock(x + 11, y + 1, z + 11, Blocks.air, 0, 3);
		world.setBlock(x + 12, y + 1, z + 11, Blocks.air, 0, 3);
		world.setBlock(x + 13, y + 1, z + 11, Blocks.stone_pressure_plate, 0, 3);
		world.setBlock(x + 14, y + 1, z + 11, Blocks.air, 0, 3);
		world.setBlock(x + 15, y + 1, z + 11, Blocks.air, 0, 3);
		world.setBlock(x + 16, y + 1, z + 11, Blocks.air, 0, 3);
		world.setBlock(x + 17, y + 1, z + 11, Blocks.air, 0, 3);
		world.setBlock(x + 18, y + 1, z + 11, Blocks.air, 0, 3);
		world.setBlock(x + 19, y + 1, z + 11, Blocks.air, 0, 3);
		world.setBlock(x + 20, y + 1, z + 11, Blocks.air, 0, 3);
		world.setBlock(x + 21, y + 1, z + 11, Blocks.air, 0, 3);
		world.setBlock(x + 22, y + 1, z + 11, Blocks.stone, 0, 3);
		world.setBlock(x + 0, y + 1, z + 12, Blocks.stone, 0, 3);
		world.setBlock(x + 1, y + 1, z + 12, Blocks.air, 0, 3);
		world.setBlock(x + 2, y + 1, z + 12, Blocks.air, 0, 3);
		world.setBlock(x + 3, y + 1, z + 12, Blocks.air, 0, 3);
		world.setBlock(x + 4, y + 1, z + 12, Blocks.air, 0, 3);
		world.setBlock(x + 5, y + 1, z + 12, Blocks.air, 0, 3);
		world.setBlock(x + 6, y + 1, z + 12, Blocks.air, 0, 3);
		world.setBlock(x + 7, y + 1, z + 12, Blocks.air, 0, 3);
		world.setBlock(x + 8, y + 1, z + 12, Blocks.air, 0, 3);
		world.setBlock(x + 9, y + 1, z + 12, Blocks.air, 0, 3);
		world.setBlock(x + 10, y + 1, z + 12, Blocks.air, 0, 3);
		world.setBlock(x + 11, y + 1, z + 12, Blocks.air, 0, 3);
		world.setBlock(x + 12, y + 1, z + 12, Blocks.air, 0, 3);
		world.setBlock(x + 13, y + 1, z + 12, Blocks.air, 0, 3);
		world.setBlock(x + 14, y + 1, z + 12, Blocks.air, 0, 3);
		world.setBlock(x + 15, y + 1, z + 12, Blocks.air, 0, 3);
		world.setBlock(x + 16, y + 1, z + 12, Blocks.air, 0, 3);
		world.setBlock(x + 17, y + 1, z + 12, Blocks.air, 0, 3);
		world.setBlock(x + 18, y + 1, z + 12, Blocks.air, 0, 3);
		world.setBlock(x + 19, y + 1, z + 12, Blocks.air, 0, 3);
		world.setBlock(x + 20, y + 1, z + 12, Blocks.air, 0, 3);
		world.setBlock(x + 21, y + 1, z + 12, Blocks.air, 0, 3);
		world.setBlock(x + 22, y + 1, z + 12, Blocks.stone, 0, 3);
		world.setBlock(x + 0, y + 1, z + 13, Blocks.stone, 0, 3);
		world.setBlock(x + 1, y + 1, z + 13, Blocks.air, 0, 3);
		world.setBlock(x + 2, y + 1, z + 13, Blocks.air, 0, 3);
		world.setBlock(x + 3, y + 1, z + 13, Blocks.air, 0, 3);
		world.setBlock(x + 4, y + 1, z + 13, Blocks.air, 0, 3);
		world.setBlock(x + 5, y + 1, z + 13, Blocks.air, 0, 3);
		world.setBlock(x + 6, y + 1, z + 13, Blocks.air, 0, 3);
		world.setBlock(x + 7, y + 1, z + 13, Blocks.air, 0, 3);
		world.setBlock(x + 8, y + 1, z + 13, Blocks.air, 0, 3);
		world.setBlock(x + 9, y + 1, z + 13, Blocks.air, 0, 3);
		world.setBlock(x + 10, y + 1, z + 13, Blocks.air, 0, 3);
		world.setBlock(x + 11, y + 1, z + 13, Blocks.air, 0, 3);
		world.setBlock(x + 12, y + 1, z + 13, Blocks.air, 0, 3);
		world.setBlock(x + 13, y + 1, z + 13, Blocks.air, 0, 3);
		world.setBlock(x + 14, y + 1, z + 13, Blocks.stone_stairs, 0, 3);
		world.setBlock(x + 15, y + 1, z + 13, Blocks.cobblestone, 0, 3);
		world.setBlock(x + 16, y + 1, z + 13, Blocks.cobblestone, 0, 3);
		world.setBlock(x + 17, y + 1, z + 13, Blocks.air, 0, 3);
		world.setBlock(x + 18, y + 1, z + 13, Blocks.air, 0, 3);
		world.setBlock(x + 19, y + 1, z + 13, Blocks.air, 0, 3);
		world.setBlock(x + 20, y + 1, z + 13, Blocks.air, 0, 3);
		world.setBlock(x + 21, y + 1, z + 13, Blocks.air, 0, 3);
		world.setBlock(x + 22, y + 1, z + 13, Blocks.stone, 0, 3);
		world.setBlock(x + 0, y + 1, z + 14, Blocks.stone, 0, 3);
		world.setBlock(x + 1, y + 1, z + 14, Blocks.air, 0, 3);
		world.setBlock(x + 2, y + 1, z + 14, Blocks.air, 0, 3);
		world.setBlock(x + 3, y + 1, z + 14, Blocks.air, 0, 3);
		world.setBlock(x + 4, y + 1, z + 14, Blocks.air, 0, 3);
		world.setBlock(x + 5, y + 1, z + 14, Blocks.air, 0, 3);
		world.setBlock(x + 6, y + 1, z + 14, Blocks.air, 0, 3);
		world.setBlock(x + 7, y + 1, z + 14, Blocks.air, 0, 3);
		world.setBlock(x + 8, y + 1, z + 14, Blocks.air, 0, 3);
		world.setBlock(x + 9, y + 1, z + 14, Blocks.air, 0, 3);
		world.setBlock(x + 10, y + 1, z + 14, Blocks.air, 0, 3);
		world.setBlock(x + 11, y + 1, z + 14, Blocks.air, 0, 3);
		world.setBlock(x + 12, y + 1, z + 14, Blocks.air, 0, 3);
		world.setBlock(x + 13, y + 1, z + 14, Blocks.air, 0, 3);
		world.setBlock(x + 14, y + 1, z + 14, Blocks.stone_stairs, 0, 3);
		world.setBlock(x + 15, y + 1, z + 14, Blocks.cobblestone, 0, 3);
		world.setBlock(x + 16, y + 1, z + 14, Blocks.cobblestone, 0, 3);
		world.setBlock(x + 17, y + 1, z + 14, Blocks.air, 0, 3);
		world.setBlock(x + 18, y + 1, z + 14, Blocks.air, 0, 3);
		world.setBlock(x + 19, y + 1, z + 14, Blocks.air, 0, 3);
		world.setBlock(x + 20, y + 1, z + 14, Blocks.air, 0, 3);
		world.setBlock(x + 21, y + 1, z + 14, Blocks.air, 0, 3);
		world.setBlock(x + 22, y + 1, z + 14, Blocks.stone, 0, 3);
		world.setBlock(x + 0, y + 1, z + 15, Blocks.stone, 0, 3);
		world.setBlock(x + 1, y + 1, z + 15, Blocks.air, 0, 3);
		world.setBlock(x + 2, y + 1, z + 15, Blocks.air, 0, 3);
		world.setBlock(x + 3, y + 1, z + 15, Blocks.air, 0, 3);
		world.setBlock(x + 4, y + 1, z + 15, Blocks.air, 0, 3);
		world.setBlock(x + 5, y + 1, z + 15, Blocks.air, 0, 3);
		world.setBlock(x + 6, y + 1, z + 15, Blocks.air, 0, 3);
		world.setBlock(x + 7, y + 1, z + 15, Blocks.air, 0, 3);
		world.setBlock(x + 8, y + 1, z + 15, Blocks.air, 0, 3);
		world.setBlock(x + 9, y + 1, z + 15, Blocks.air, 0, 3);
		world.setBlock(x + 10, y + 1, z + 15, Blocks.air, 0, 3);
		world.setBlock(x + 11, y + 1, z + 15, Blocks.air, 0, 3);
		world.setBlock(x + 12, y + 1, z + 15, Blocks.air, 0, 3);
		world.setBlock(x + 13, y + 1, z + 15, Blocks.air, 0, 3);
		world.setBlock(x + 14, y + 1, z + 15, Blocks.air, 0, 3);
		world.setBlock(x + 15, y + 1, z + 15, Blocks.air, 0, 3);
		world.setBlock(x + 16, y + 1, z + 15, Blocks.air, 0, 3);
		world.setBlock(x + 17, y + 1, z + 15, Blocks.air, 0, 3);
		world.setBlock(x + 18, y + 1, z + 15, Blocks.air, 0, 3);
		world.setBlock(x + 19, y + 1, z + 15, Blocks.air, 0, 3);
		world.setBlock(x + 20, y + 1, z + 15, Blocks.air, 0, 3);
		world.setBlock(x + 21, y + 1, z + 15, Blocks.air, 0, 3);
		world.setBlock(x + 22, y + 1, z + 15, Blocks.stone, 0, 3);
		world.setBlock(x + 0, y + 1, z + 16, Blocks.stone, 0, 3);
		world.setBlock(x + 1, y + 1, z + 16, Blocks.air, 0, 3);
		world.setBlock(x + 2, y + 1, z + 16, Blocks.air, 0, 3);
		world.setBlock(x + 3, y + 1, z + 16, Blocks.air, 0, 3);
		world.setBlock(x + 4, y + 1, z + 16, Blocks.air, 0, 3);
		world.setBlock(x + 5, y + 1, z + 16, Blocks.air, 0, 3);
		world.setBlock(x + 6, y + 1, z + 16, Blocks.log, 0, 3);
		world.setBlock(x + 7, y + 1, z + 16, Blocks.log, 0, 3);
		world.setBlock(x + 8, y + 1, z + 16, Blocks.log, 0, 3);
		world.setBlock(x + 9, y + 1, z + 16, Blocks.stone_pressure_plate, 0, 3);
		world.setBlock(x + 10, y + 1, z + 16, Blocks.air, 0, 3);
		world.setBlock(x + 11, y + 1, z + 16, Blocks.air, 0, 3);
		world.setBlock(x + 12, y + 1, z + 16, Blocks.air, 0, 3);
		world.setBlock(x + 13, y + 1, z + 16, Blocks.air, 0, 3);
		world.setBlock(x + 14, y + 1, z + 16, Blocks.air, 0, 3);
		world.setBlock(x + 15, y + 1, z + 16, Blocks.air, 0, 3);
		world.setBlock(x + 16, y + 1, z + 16, Blocks.stone_pressure_plate, 0, 3);
		world.setBlock(x + 17, y + 1, z + 16, Blocks.air, 0, 3);
		world.setBlock(x + 18, y + 1, z + 16, Blocks.air, 0, 3);
		world.setBlock(x + 19, y + 1, z + 16, Blocks.air, 0, 3);
		world.setBlock(x + 20, y + 1, z + 16, Blocks.air, 0, 3);
		world.setBlock(x + 21, y + 1, z + 16, Blocks.air, 0, 3);
		world.setBlock(x + 22, y + 1, z + 16, Blocks.stone, 0, 3);
		world.setBlock(x + 0, y + 1, z + 17, Blocks.stone, 0, 3);
		world.setBlock(x + 1, y + 1, z + 17, Blocks.stone, 0, 3);
		world.setBlock(x + 2, y + 1, z + 17, Blocks.stone, 0, 3);
		world.setBlock(x + 3, y + 1, z + 17, Blocks.stone, 0, 3);
		world.setBlock(x + 4, y + 1, z + 17, Blocks.stone, 0, 3);
		world.setBlock(x + 5, y + 1, z + 17, Blocks.stone, 0, 3);
		world.setBlock(x + 6, y + 1, z + 17, Blocks.stone, 0, 3);
		world.setBlock(x + 7, y + 1, z + 17, Blocks.stone, 0, 3);
		world.setBlock(x + 8, y + 1, z + 17, Blocks.stone, 0, 3);
		world.setBlock(x + 9, y + 1, z + 17, Blocks.wooden_door, 3, 3);
		world.setBlock(x + 10, y + 1, z + 17, Blocks.stone, 0, 3);
		world.setBlock(x + 11, y + 1, z + 17, Blocks.stone, 0, 3);
		world.setBlock(x + 12, y + 1, z + 17, Blocks.stone, 0, 3);
		world.setBlock(x + 13, y + 1, z + 17, Blocks.stone, 0, 3);
		world.setBlock(x + 14, y + 1, z + 17, Blocks.stone, 0, 3);
		world.setBlock(x + 15, y + 1, z + 17, Blocks.stone, 0, 3);
		world.setBlock(x + 16, y + 1, z + 17, Blocks.wooden_door, 3, 3);
		world.setBlock(x + 17, y + 1, z + 17, Blocks.wooden_door, 6, 3);
		world.setBlock(x + 18, y + 1, z + 17, Blocks.stone, 0, 3);
		world.setBlock(x + 19, y + 1, z + 17, Blocks.stone, 0, 3);
		world.setBlock(x + 20, y + 1, z + 17, Blocks.stone, 0, 3);
		world.setBlock(x + 21, y + 1, z + 17, Blocks.stone, 0, 3);
		world.setBlock(x + 22, y + 1, z + 17, Blocks.stone, 0, 3);
		world.setBlock(x + 0, y + 2, z + 0, Blocks.stone, 0, 3);
		world.setBlock(x + 1, y + 2, z + 0, Blocks.glass, 0, 3);
		world.setBlock(x + 2, y + 2, z + 0, Blocks.glass, 0, 3);
		world.setBlock(x + 3, y + 2, z + 0, Blocks.glass, 0, 3);
		world.setBlock(x + 4, y + 2, z + 0, Blocks.stone, 0, 3);
		world.setBlock(x + 5, y + 2, z + 0, Blocks.glass, 0, 3);
		world.setBlock(x + 6, y + 2, z + 0, Blocks.glass, 0, 3);
		world.setBlock(x + 7, y + 2, z + 0, Blocks.glass, 0, 3);
		world.setBlock(x + 8, y + 2, z + 0, Blocks.stone, 0, 3);
		world.setBlock(x + 9, y + 2, z + 0, Blocks.air, 0, 3);
		world.setBlock(x + 10, y + 2, z + 0, Blocks.air, 0, 3);
		world.setBlock(x + 11, y + 2, z + 0, Blocks.air, 0, 3);
		world.setBlock(x + 12, y + 2, z + 0, Blocks.air, 0, 3);
		world.setBlock(x + 13, y + 2, z + 0, Blocks.air, 0, 3);
		world.setBlock(x + 14, y + 2, z + 0, Blocks.air, 0, 3);
		world.setBlock(x + 15, y + 2, z + 0, Blocks.air, 0, 3);
		world.setBlock(x + 16, y + 2, z + 0, Blocks.air, 0, 3);
		world.setBlock(x + 17, y + 2, z + 0, Blocks.air, 0, 3);
		world.setBlock(x + 18, y + 2, z + 0, Blocks.air, 0, 3);
		world.setBlock(x + 19, y + 2, z + 0, Blocks.air, 0, 3);
		world.setBlock(x + 20, y + 2, z + 0, Blocks.air, 0, 3);
		world.setBlock(x + 21, y + 2, z + 0, Blocks.air, 0, 3);
		world.setBlock(x + 22, y + 2, z + 0, Blocks.air, 0, 3);
		world.setBlock(x + 0, y + 2, z + 1, Blocks.glass, 0, 3);
		world.setBlock(x + 1, y + 2, z + 1, Blocks.air, 0, 3);
		world.setBlock(x + 2, y + 2, z + 1, Blocks.air, 0, 3);
		world.setBlock(x + 3, y + 2, z + 1, Blocks.air, 0, 3);
		world.setBlock(x + 4, y + 2, z + 1, Blocks.air, 0, 3);
		world.setBlock(x + 5, y + 2, z + 1, Blocks.air, 0, 3);
		world.setBlock(x + 6, y + 2, z + 1, Blocks.air, 0, 3);
		world.setBlock(x + 7, y + 2, z + 1, Blocks.air, 0, 3);
		world.setBlock(x + 8, y + 2, z + 1, Blocks.glass, 0, 3);
		world.setBlock(x + 9, y + 2, z + 1, Blocks.air, 0, 3);
		world.setBlock(x + 10, y + 2, z + 1, Blocks.air, 0, 3);
		world.setBlock(x + 11, y + 2, z + 1, Blocks.air, 0, 3);
		world.setBlock(x + 12, y + 2, z + 1, Blocks.air, 0, 3);
		world.setBlock(x + 13, y + 2, z + 1, Blocks.air, 0, 3);
		world.setBlock(x + 14, y + 2, z + 1, Blocks.air, 0, 3);
		world.setBlock(x + 15, y + 2, z + 1, Blocks.air, 0, 3);
		world.setBlock(x + 16, y + 2, z + 1, Blocks.air, 0, 3);
		world.setBlock(x + 17, y + 2, z + 1, Blocks.air, 0, 3);
		world.setBlock(x + 18, y + 2, z + 1, Blocks.air, 0, 3);
		world.setBlock(x + 19, y + 2, z + 1, Blocks.air, 0, 3);
		world.setBlock(x + 20, y + 2, z + 1, Blocks.air, 0, 3);
		world.setBlock(x + 21, y + 2, z + 1, Blocks.air, 0, 3);
		world.setBlock(x + 22, y + 2, z + 1, Blocks.air, 0, 3);
		world.setBlock(x + 0, y + 2, z + 2, Blocks.glass, 0, 3);
		world.setBlock(x + 1, y + 2, z + 2, Blocks.air, 0, 3);
		world.setBlock(x + 2, y + 2, z + 2, Blocks.air, 0, 3);
		world.setBlock(x + 3, y + 2, z + 2, Blocks.air, 0, 3);
		world.setBlock(x + 4, y + 2, z + 2, Blocks.air, 0, 3);
		world.setBlock(x + 5, y + 2, z + 2, Blocks.air, 0, 3);
		world.setBlock(x + 6, y + 2, z + 2, Blocks.air, 0, 3);
		world.setBlock(x + 7, y + 2, z + 2, Blocks.air, 0, 3);
		world.setBlock(x + 8, y + 2, z + 2, Blocks.glass, 0, 3);
		world.setBlock(x + 9, y + 2, z + 2, Blocks.air, 0, 3);
		world.setBlock(x + 10, y + 2, z + 2, Blocks.air, 0, 3);
		world.setBlock(x + 11, y + 2, z + 2, Blocks.air, 0, 3);
		world.setBlock(x + 12, y + 2, z + 2, Blocks.air, 0, 3);
		world.setBlock(x + 13, y + 2, z + 2, Blocks.air, 0, 3);
		world.setBlock(x + 14, y + 2, z + 2, Blocks.air, 0, 3);
		world.setBlock(x + 15, y + 2, z + 2, Blocks.air, 0, 3);
		world.setBlock(x + 16, y + 2, z + 2, Blocks.air, 0, 3);
		world.setBlock(x + 17, y + 2, z + 2, Blocks.air, 0, 3);
		world.setBlock(x + 18, y + 2, z + 2, Blocks.air, 0, 3);
		world.setBlock(x + 19, y + 2, z + 2, Blocks.air, 0, 3);
		world.setBlock(x + 20, y + 2, z + 2, Blocks.air, 0, 3);
		world.setBlock(x + 21, y + 2, z + 2, Blocks.air, 0, 3);
		world.setBlock(x + 22, y + 2, z + 2, Blocks.air, 0, 3);
		world.setBlock(x + 0, y + 2, z + 3, Blocks.glass, 0, 3);
		world.setBlock(x + 1, y + 2, z + 3, Blocks.air, 0, 3);
		world.setBlock(x + 2, y + 2, z + 3, Blocks.air, 0, 3);
		world.setBlock(x + 3, y + 2, z + 3, Blocks.air, 0, 3);
		world.setBlock(x + 4, y + 2, z + 3, Blocks.air, 0, 3);
		world.setBlock(x + 5, y + 2, z + 3, Blocks.air, 0, 3);
		world.setBlock(x + 6, y + 2, z + 3, Blocks.air, 0, 3);
		world.setBlock(x + 7, y + 2, z + 3, Blocks.air, 0, 3);
		world.setBlock(x + 8, y + 2, z + 3, Blocks.stone, 0, 3);
		world.setBlock(x + 9, y + 2, z + 3, Blocks.air, 0, 3);
		world.setBlock(x + 10, y + 2, z + 3, Blocks.air, 0, 3);
		world.setBlock(x + 11, y + 2, z + 3, Blocks.air, 0, 3);
		world.setBlock(x + 12, y + 2, z + 3, Blocks.air, 0, 3);
		world.setBlock(x + 13, y + 2, z + 3, Blocks.air, 0, 3);
		world.setBlock(x + 14, y + 2, z + 3, Blocks.air, 0, 3);
		world.setBlock(x + 15, y + 2, z + 3, Blocks.air, 0, 3);
		world.setBlock(x + 16, y + 2, z + 3, Blocks.air, 0, 3);
		world.setBlock(x + 17, y + 2, z + 3, Blocks.air, 0, 3);
		world.setBlock(x + 18, y + 2, z + 3, Blocks.air, 0, 3);
		world.setBlock(x + 19, y + 2, z + 3, Blocks.air, 0, 3);
		world.setBlock(x + 20, y + 2, z + 3, Blocks.air, 0, 3);
		world.setBlock(x + 21, y + 2, z + 3, Blocks.air, 0, 3);
		world.setBlock(x + 22, y + 2, z + 3, Blocks.air, 0, 3);
		world.setBlock(x + 0, y + 2, z + 4, Blocks.stone, 0, 3);
		world.setBlock(x + 1, y + 2, z + 4, Blocks.air, 0, 3);
		world.setBlock(x + 2, y + 2, z + 4, Blocks.air, 0, 3);
		world.setBlock(x + 3, y + 2, z + 4, Blocks.air, 0, 3);
		world.setBlock(x + 4, y + 2, z + 4, Blocks.air, 0, 3);
		world.setBlock(x + 5, y + 2, z + 4, Blocks.air, 0, 3);
		world.setBlock(x + 6, y + 2, z + 4, Blocks.air, 0, 3);
		world.setBlock(x + 7, y + 2, z + 4, Blocks.air, 0, 3);
		world.setBlock(x + 8, y + 2, z + 4, Blocks.wooden_door, 13, 3);
		world.setBlock(x + 9, y + 2, z + 4, Blocks.air, 0, 3);
		world.setBlock(x + 10, y + 2, z + 4, Blocks.air, 0, 3);
		world.setBlock(x + 11, y + 2, z + 4, Blocks.air, 0, 3);
		world.setBlock(x + 12, y + 2, z + 4, Blocks.air, 0, 3);
		world.setBlock(x + 13, y + 2, z + 4, Blocks.air, 0, 3);
		world.setBlock(x + 14, y + 2, z + 4, Blocks.air, 0, 3);
		world.setBlock(x + 15, y + 2, z + 4, Blocks.air, 0, 3);
		world.setBlock(x + 16, y + 2, z + 4, Blocks.air, 0, 3);
		world.setBlock(x + 17, y + 2, z + 4, Blocks.air, 0, 3);
		world.setBlock(x + 18, y + 2, z + 4, Blocks.air, 0, 3);
		world.setBlock(x + 19, y + 2, z + 4, Blocks.air, 0, 3);
		world.setBlock(x + 20, y + 2, z + 4, Blocks.air, 0, 3);
		world.setBlock(x + 21, y + 2, z + 4, Blocks.air, 0, 3);
		world.setBlock(x + 22, y + 2, z + 4, Blocks.air, 0, 3);
		world.setBlock(x + 0, y + 2, z + 5, Blocks.glass, 0, 3);
		world.setBlock(x + 1, y + 2, z + 5, Blocks.air, 0, 3);
		world.setBlock(x + 2, y + 2, z + 5, Blocks.air, 0, 3);
		world.setBlock(x + 3, y + 2, z + 5, Blocks.air, 0, 3);
		world.setBlock(x + 4, y + 2, z + 5, Blocks.stone_pressure_plate, 0, 3);
		world.setBlock(x + 5, y + 2, z + 5, Blocks.air, 0, 3);
		world.setBlock(x + 6, y + 2, z + 5, Blocks.air, 0, 3);
		world.setBlock(x + 7, y + 2, z + 5, Blocks.air, 0, 3);
		world.setBlock(x + 8, y + 2, z + 5, Blocks.wooden_door, 10, 3);
		world.setBlock(x + 9, y + 2, z + 5, Blocks.air, 0, 3);
		world.setBlock(x + 10, y + 2, z + 5, Blocks.air, 0, 3);
		world.setBlock(x + 11, y + 2, z + 5, Blocks.air, 0, 3);
		world.setBlock(x + 12, y + 2, z + 5, Blocks.air, 0, 3);
		world.setBlock(x + 13, y + 2, z + 5, Blocks.air, 0, 3);
		world.setBlock(x + 14, y + 2, z + 5, Blocks.air, 0, 3);
		world.setBlock(x + 15, y + 2, z + 5, Blocks.air, 0, 3);
		world.setBlock(x + 16, y + 2, z + 5, Blocks.air, 0, 3);
		world.setBlock(x + 17, y + 2, z + 5, Blocks.air, 0, 3);
		world.setBlock(x + 18, y + 2, z + 5, Blocks.air, 0, 3);
		world.setBlock(x + 19, y + 2, z + 5, Blocks.air, 0, 3);
		world.setBlock(x + 20, y + 2, z + 5, Blocks.air, 0, 3);
		world.setBlock(x + 21, y + 2, z + 5, Blocks.air, 0, 3);
		world.setBlock(x + 22, y + 2, z + 5, Blocks.air, 0, 3);
		world.setBlock(x + 0, y + 2, z + 6, Blocks.glass, 0, 3);
		world.setBlock(x + 1, y + 2, z + 6, Blocks.air, 0, 3);
		world.setBlock(x + 2, y + 2, z + 6, Blocks.air, 0, 3);
		world.setBlock(x + 3, y + 2, z + 6, Blocks.stone_pressure_plate, 0, 3);
		world.setBlock(x + 5, y + 2, z + 6, Blocks.stone_pressure_plate, 0, 3);
		world.setBlock(x + 6, y + 2, z + 6, Blocks.air, 0, 3);
		world.setBlock(x + 7, y + 2, z + 6, Blocks.air, 0, 3);
		world.setBlock(x + 8, y + 2, z + 6, Blocks.stone, 0, 3);
		world.setBlock(x + 9, y + 2, z + 6, Blocks.air, 0, 3);
		world.setBlock(x + 10, y + 2, z + 6, Blocks.air, 0, 3);
		world.setBlock(x + 11, y + 2, z + 6, Blocks.air, 0, 3);
		world.setBlock(x + 12, y + 2, z + 6, Blocks.air, 0, 3);
		world.setBlock(x + 13, y + 2, z + 6, Blocks.air, 0, 3);
		world.setBlock(x + 14, y + 2, z + 6, Blocks.air, 0, 3);
		world.setBlock(x + 15, y + 2, z + 6, Blocks.air, 0, 3);
		world.setBlock(x + 16, y + 2, z + 6, Blocks.air, 0, 3);
		world.setBlock(x + 17, y + 2, z + 6, Blocks.stone, 0, 3);
		world.setBlock(x + 18, y + 2, z + 6, Blocks.stone, 0, 3);
		world.setBlock(x + 19, y + 2, z + 6, Blocks.wooden_door, 12, 3);
		world.setBlock(x + 20, y + 2, z + 6, Blocks.wooden_door, 9, 3);
		world.setBlock(x + 21, y + 2, z + 6, Blocks.stone, 0, 3);
		world.setBlock(x + 22, y + 2, z + 6, Blocks.stone, 0, 3);
		world.setBlock(x + 0, y + 2, z + 7, Blocks.stone, 0, 3);
		world.setBlock(x + 1, y + 2, z + 7, Blocks.air, 0, 3);
		world.setBlock(x + 2, y + 2, z + 7, Blocks.air, 0, 3);
		world.setBlock(x + 3, y + 2, z + 7, Blocks.air, 0, 3);
		world.setBlock(x + 4, y + 2, z + 7, Blocks.stone_pressure_plate, 0, 3);
		world.setBlock(x + 5, y + 2, z + 7, Blocks.air, 0, 3);
		world.setBlock(x + 6, y + 2, z + 7, Blocks.air, 0, 3);
		world.setBlock(x + 7, y + 2, z + 7, Blocks.air, 0, 3);
		world.setBlock(x + 8, y + 2, z + 7, Blocks.glass, 0, 3);
		world.setBlock(x + 9, y + 2, z + 7, Blocks.air, 0, 3);
		world.setBlock(x + 10, y + 2, z + 7, Blocks.air, 0, 3);
		world.setBlock(x + 11, y + 2, z + 7, Blocks.air, 0, 3);
		world.setBlock(x + 12, y + 2, z + 7, Blocks.air, 0, 3);
		world.setBlock(x + 13, y + 2, z + 7, Blocks.air, 0, 3);
		world.setBlock(x + 14, y + 2, z + 7, Blocks.air, 0, 3);
		world.setBlock(x + 15, y + 2, z + 7, Blocks.air, 0, 3);
		world.setBlock(x + 16, y + 2, z + 7, Blocks.air, 0, 3);
		world.setBlock(x + 17, y + 2, z + 7, Blocks.glass, 0, 3);
		world.setBlock(x + 18, y + 2, z + 7, Blocks.air, 0, 3);
		world.setBlock(x + 19, y + 2, z + 7, Blocks.air, 0, 3);
		world.setBlock(x + 20, y + 2, z + 7, Blocks.air, 0, 3);
		world.setBlock(x + 21, y + 2, z + 7, Blocks.air, 0, 3);
		world.setBlock(x + 22, y + 2, z + 7, Blocks.glass, 0, 3);
		world.setBlock(x + 0, y + 2, z + 8, Blocks.wooden_door, 8, 3);
		world.setBlock(x + 1, y + 2, z + 8, Blocks.air, 0, 3);
		world.setBlock(x + 2, y + 2, z + 8, Blocks.air, 0, 3);
		world.setBlock(x + 3, y + 2, z + 8, Blocks.air, 0, 3);
		world.setBlock(x + 4, y + 2, z + 8, Blocks.air, 0, 3);
		world.setBlock(x + 5, y + 2, z + 8, Blocks.air, 0, 3);
		world.setBlock(x + 6, y + 2, z + 8, Blocks.air, 0, 3);
		world.setBlock(x + 7, y + 2, z + 8, Blocks.air, 0, 3);
		world.setBlock(x + 8, y + 2, z + 8, Blocks.glass, 0, 3);
		world.setBlock(x + 9, y + 2, z + 8, Blocks.air, 0, 3);
		world.setBlock(x + 10, y + 2, z + 8, Blocks.air, 0, 3);
		world.setBlock(x + 11, y + 2, z + 8, Blocks.air, 0, 3);
		world.setBlock(x + 12, y + 2, z + 8, Blocks.air, 0, 3);
		world.setBlock(x + 13, y + 2, z + 8, Blocks.air, 0, 3);
		world.setBlock(x + 14, y + 2, z + 8, Blocks.air, 0, 3);
		world.setBlock(x + 15, y + 2, z + 8, Blocks.air, 0, 3);
		world.setBlock(x + 16, y + 2, z + 8, Blocks.air, 0, 3);
		world.setBlock(x + 17, y + 2, z + 8, Blocks.glass, 0, 3);
		world.setBlock(x + 19, y + 2, z + 8, Blocks.air, 0, 3);
		world.setBlock(x + 20, y + 2, z + 8, Blocks.air, 0, 3);
		world.setBlock(x + 22, y + 2, z + 8, Blocks.glass, 0, 3);
		world.setBlock(x + 0, y + 2, z + 9, Blocks.wooden_door, 15, 3);
		world.setBlock(x + 1, y + 2, z + 9, Blocks.air, 0, 3);
		world.setBlock(x + 2, y + 2, z + 9, Blocks.air, 0, 3);
		world.setBlock(x + 3, y + 2, z + 9, Blocks.air, 0, 3);
		world.setBlock(x + 4, y + 2, z + 9, Blocks.air, 0, 3);
		world.setBlock(x + 5, y + 2, z + 9, Blocks.air, 0, 3);
		world.setBlock(x + 6, y + 2, z + 9, Blocks.air, 0, 3);
		world.setBlock(x + 7, y + 2, z + 9, Blocks.air, 0, 3);
		world.setBlock(x + 8, y + 2, z + 9, Blocks.glass, 0, 3);
		world.setBlock(x + 9, y + 2, z + 9, Blocks.air, 0, 3);
		world.setBlock(x + 10, y + 2, z + 9, Blocks.air, 0, 3);
		world.setBlock(x + 11, y + 2, z + 9, Blocks.air, 0, 3);
		world.setBlock(x + 12, y + 2, z + 9, Blocks.air, 0, 3);
		world.setBlock(x + 13, y + 2, z + 9, Blocks.air, 0, 3);
		world.setBlock(x + 14, y + 2, z + 9, Blocks.air, 0, 3);
		world.setBlock(x + 15, y + 2, z + 9, Blocks.air, 0, 3);
		world.setBlock(x + 16, y + 2, z + 9, Blocks.air, 0, 3);
		world.setBlock(x + 17, y + 2, z + 9, Blocks.glass, 0, 3);
		world.setBlock(x + 18, y + 2, z + 9, Blocks.air, 0, 3);
		world.setBlock(x + 19, y + 2, z + 9, Blocks.air, 0, 3);
		world.setBlock(x + 20, y + 2, z + 9, Blocks.air, 0, 3);
		world.setBlock(x + 21, y + 2, z + 9, Blocks.air, 0, 3);
		world.setBlock(x + 22, y + 2, z + 9, Blocks.glass, 0, 3);
		world.setBlock(x + 0, y + 2, z + 10, Blocks.stone, 0, 3);
		world.setBlock(x + 1, y + 2, z + 10, Blocks.air, 0, 3);
		world.setBlock(x + 2, y + 2, z + 10, Blocks.air, 0, 3);
		world.setBlock(x + 3, y + 2, z + 10, Blocks.air, 0, 3);
		world.setBlock(x + 4, y + 2, z + 10, Blocks.air, 0, 3);
		world.setBlock(x + 5, y + 2, z + 10, Blocks.air, 0, 3);
		world.setBlock(x + 6, y + 2, z + 10, Blocks.air, 0, 3);
		world.setBlock(x + 7, y + 2, z + 10, Blocks.air, 0, 3);
		world.setBlock(x + 8, y + 2, z + 10, Blocks.stone, 0, 3);
		world.setBlock(x + 9, y + 2, z + 10, Blocks.glass, 0, 3);
		world.setBlock(x + 10, y + 2, z + 10, Blocks.glass, 0, 3);
		world.setBlock(x + 11, y + 2, z + 10, Blocks.stone, 0, 3);
		world.setBlock(x + 12, y + 2, z + 10, Blocks.wooden_door, 12, 3);
		world.setBlock(x + 13, y + 2, z + 10, Blocks.wooden_door, 9, 3);
		world.setBlock(x + 14, y + 2, z + 10, Blocks.stone, 0, 3);
		world.setBlock(x + 15, y + 2, z + 10, Blocks.glass, 0, 3);
		world.setBlock(x + 16, y + 2, z + 10, Blocks.glass, 0, 3);
		world.setBlock(x + 17, y + 2, z + 10, Blocks.stone, 0, 3);
		world.setBlock(x + 18, y + 2, z + 10, Blocks.air, 0, 3);
		world.setBlock(x + 19, y + 2, z + 10, Blocks.air, 0, 3);
		world.setBlock(x + 20, y + 2, z + 10, Blocks.air, 0, 3);
		world.setBlock(x + 21, y + 2, z + 10, Blocks.air, 0, 3);
		world.setBlock(x + 22, y + 2, z + 10, Blocks.stone, 0, 3);
		world.setBlock(x + 0, y + 2, z + 11, Blocks.glass, 0, 3);
		world.setBlock(x + 1, y + 2, z + 11, Blocks.air, 0, 3);
		world.setBlock(x + 2, y + 2, z + 11, Blocks.air, 0, 3);
		world.setBlock(x + 3, y + 2, z + 11, Blocks.air, 0, 3);
		world.setBlock(x + 4, y + 2, z + 11, Blocks.air, 0, 3);
		world.setBlock(x + 5, y + 2, z + 11, Blocks.air, 0, 3);
		world.setBlock(x + 6, y + 2, z + 11, Blocks.air, 0, 3);
		world.setBlock(x + 7, y + 2, z + 11, Blocks.air, 0, 3);
		world.setBlock(x + 8, y + 2, z + 11, Blocks.air, 0, 3);
		world.setBlock(x + 9, y + 2, z + 11, Blocks.air, 0, 3);
		world.setBlock(x + 10, y + 2, z + 11, Blocks.air, 0, 3);
		world.setBlock(x + 11, y + 2, z + 11, Blocks.air, 0, 3);
		world.setBlock(x + 12, y + 2, z + 11, Blocks.air, 0, 3);
		world.setBlock(x + 13, y + 2, z + 11, Blocks.air, 0, 3);
		world.setBlock(x + 14, y + 2, z + 11, Blocks.air, 0, 3);
		world.setBlock(x + 15, y + 2, z + 11, Blocks.air, 0, 3);
		world.setBlock(x + 16, y + 2, z + 11, Blocks.air, 0, 3);
		world.setBlock(x + 17, y + 2, z + 11, Blocks.air, 0, 3);
		world.setBlock(x + 18, y + 2, z + 11, Blocks.air, 0, 3);
		world.setBlock(x + 19, y + 2, z + 11, Blocks.air, 0, 3);
		world.setBlock(x + 20, y + 2, z + 11, Blocks.air, 0, 3);
		world.setBlock(x + 21, y + 2, z + 11, Blocks.air, 0, 3);
		world.setBlock(x + 22, y + 2, z + 11, Blocks.glass, 0, 3);
		world.setBlock(x + 0, y + 2, z + 12, Blocks.glass, 0, 3);
		world.setBlock(x + 1, y + 2, z + 12, Blocks.air, 0, 3);
		world.setBlock(x + 2, y + 2, z + 12, Blocks.air, 0, 3);
		world.setBlock(x + 3, y + 2, z + 12, Blocks.air, 0, 3);
		world.setBlock(x + 4, y + 2, z + 12, Blocks.air, 0, 3);
		world.setBlock(x + 5, y + 2, z + 12, Blocks.air, 0, 3);
		world.setBlock(x + 6, y + 2, z + 12, Blocks.air, 0, 3);
		world.setBlock(x + 7, y + 2, z + 12, Blocks.air, 0, 3);
		world.setBlock(x + 8, y + 2, z + 12, Blocks.air, 0, 3);
		world.setBlock(x + 9, y + 2, z + 12, Blocks.air, 0, 3);
		world.setBlock(x + 10, y + 2, z + 12, Blocks.air, 0, 3);
		world.setBlock(x + 11, y + 2, z + 12, Blocks.air, 0, 3);
		world.setBlock(x + 12, y + 2, z + 12, Blocks.air, 0, 3);
		world.setBlock(x + 13, y + 2, z + 12, Blocks.air, 0, 3);
		world.setBlock(x + 14, y + 2, z + 12, Blocks.air, 0, 3);
		world.setBlock(x + 15, y + 2, z + 12, Blocks.air, 0, 3);
		world.setBlock(x + 16, y + 2, z + 12, Blocks.air, 0, 3);
		world.setBlock(x + 17, y + 2, z + 12, Blocks.air, 0, 3);
		world.setBlock(x + 18, y + 2, z + 12, Blocks.air, 0, 3);
		world.setBlock(x + 19, y + 2, z + 12, Blocks.air, 0, 3);
		world.setBlock(x + 20, y + 2, z + 12, Blocks.air, 0, 3);
		world.setBlock(x + 21, y + 2, z + 12, Blocks.air, 0, 3);
		world.setBlock(x + 22, y + 2, z + 12, Blocks.glass, 0, 3);
		world.setBlock(x + 0, y + 2, z + 13, Blocks.stone, 0, 3);
		world.setBlock(x + 1, y + 2, z + 13, Blocks.air, 0, 3);
		world.setBlock(x + 2, y + 2, z + 13, Blocks.air, 0, 3);
		world.setBlock(x + 3, y + 2, z + 13, Blocks.air, 0, 3);
		world.setBlock(x + 4, y + 2, z + 13, Blocks.air, 0, 3);
		world.setBlock(x + 5, y + 2, z + 13, Blocks.air, 0, 3);
		world.setBlock(x + 6, y + 2, z + 13, Blocks.air, 0, 3);
		world.setBlock(x + 7, y + 2, z + 13, Blocks.air, 0, 3);
		world.setBlock(x + 8, y + 2, z + 13, Blocks.air, 0, 3);
		world.setBlock(x + 9, y + 2, z + 13, Blocks.air, 0, 3);
		world.setBlock(x + 10, y + 2, z + 13, Blocks.air, 0, 3);
		world.setBlock(x + 11, y + 2, z + 13, Blocks.air, 0, 3);
		world.setBlock(x + 12, y + 2, z + 13, Blocks.air, 0, 3);
		world.setBlock(x + 13, y + 2, z + 13, Blocks.air, 0, 3);
		world.setBlock(x + 14, y + 2, z + 13, Blocks.air, 0, 3);
		world.setBlock(x + 15, y + 2, z + 13, Blocks.stone_stairs, 0, 3);
		world.setBlock(x + 16, y + 2, z + 13, Blocks.cobblestone, 0, 3);
		world.setBlock(x + 17, y + 2, z + 13, Blocks.cobblestone, 0, 3);
		world.setBlock(x + 18, y + 2, z + 13, Blocks.air, 0, 3);
		world.setBlock(x + 19, y + 2, z + 13, Blocks.air, 0, 3);
		world.setBlock(x + 20, y + 2, z + 13, Blocks.air, 0, 3);
		world.setBlock(x + 21, y + 2, z + 13, Blocks.air, 0, 3);
		world.setBlock(x + 22, y + 2, z + 13, Blocks.stone, 0, 3);
		world.setBlock(x + 0, y + 2, z + 14, Blocks.glass, 0, 3);
		world.setBlock(x + 1, y + 2, z + 14, Blocks.air, 0, 3);
		world.setBlock(x + 2, y + 2, z + 14, Blocks.air, 0, 3);
		world.setBlock(x + 3, y + 2, z + 14, Blocks.air, 0, 3);
		world.setBlock(x + 4, y + 2, z + 14, Blocks.air, 0, 3);
		world.setBlock(x + 5, y + 2, z + 14, Blocks.air, 0, 3);
		world.setBlock(x + 6, y + 2, z + 14, Blocks.air, 0, 3);
		world.setBlock(x + 7, y + 2, z + 14, Blocks.air, 0, 3);
		world.setBlock(x + 8, y + 2, z + 14, Blocks.air, 0, 3);
		world.setBlock(x + 9, y + 2, z + 14, Blocks.air, 0, 3);
		world.setBlock(x + 10, y + 2, z + 14, Blocks.air, 0, 3);
		world.setBlock(x + 11, y + 2, z + 14, Blocks.air, 0, 3);
		world.setBlock(x + 12, y + 2, z + 14, Blocks.air, 0, 3);
		world.setBlock(x + 13, y + 2, z + 14, Blocks.air, 0, 3);
		world.setBlock(x + 14, y + 2, z + 14, Blocks.air, 0, 3);
		world.setBlock(x + 15, y + 2, z + 14, Blocks.stone_stairs, 0, 3);
		world.setBlock(x + 16, y + 2, z + 14, Blocks.cobblestone, 0, 3);
		world.setBlock(x + 17, y + 2, z + 14, Blocks.cobblestone, 0, 3);
		world.setBlock(x + 18, y + 2, z + 14, Blocks.air, 0, 3);
		world.setBlock(x + 19, y + 2, z + 14, Blocks.air, 0, 3);
		world.setBlock(x + 20, y + 2, z + 14, Blocks.air, 0, 3);
		world.setBlock(x + 21, y + 2, z + 14, Blocks.air, 0, 3);
		world.setBlock(x + 22, y + 2, z + 14, Blocks.glass, 0, 3);
		world.setBlock(x + 0, y + 2, z + 15, Blocks.glass, 0, 3);
		world.setBlock(x + 1, y + 2, z + 15, Blocks.air, 0, 3);
		world.setBlock(x + 2, y + 2, z + 15, Blocks.air, 0, 3);
		world.setBlock(x + 3, y + 2, z + 15, Blocks.air, 0, 3);
		world.setBlock(x + 4, y + 2, z + 15, Blocks.air, 0, 3);
		world.setBlock(x + 5, y + 2, z + 15, Blocks.air, 0, 3);
		world.setBlock(x + 6, y + 2, z + 15, Blocks.air, 0, 3);
		world.setBlock(x + 7, y + 2, z + 15, Blocks.air, 0, 3);
		world.setBlock(x + 8, y + 2, z + 15, Blocks.air, 0, 3);
		world.setBlock(x + 9, y + 2, z + 15, Blocks.air, 0, 3);
		world.setBlock(x + 10, y + 2, z + 15, Blocks.air, 0, 3);
		world.setBlock(x + 11, y + 2, z + 15, Blocks.air, 0, 3);
		world.setBlock(x + 12, y + 2, z + 15, Blocks.air, 0, 3);
		world.setBlock(x + 13, y + 2, z + 15, Blocks.air, 0, 3);
		world.setBlock(x + 14, y + 2, z + 15, Blocks.air, 0, 3);
		world.setBlock(x + 15, y + 2, z + 15, Blocks.air, 0, 3);
		world.setBlock(x + 16, y + 2, z + 15, Blocks.air, 0, 3);
		world.setBlock(x + 17, y + 2, z + 15, Blocks.air, 0, 3);
		world.setBlock(x + 18, y + 2, z + 15, Blocks.air, 0, 3);
		world.setBlock(x + 19, y + 2, z + 15, Blocks.air, 0, 3);
		world.setBlock(x + 20, y + 2, z + 15, Blocks.air, 0, 3);
		world.setBlock(x + 21, y + 2, z + 15, Blocks.air, 0, 3);
		world.setBlock(x + 22, y + 2, z + 15, Blocks.glass, 0, 3);
		world.setBlock(x + 0, y + 2, z + 16, Blocks.glass, 0, 3);
		world.setBlock(x + 1, y + 2, z + 16, Blocks.air, 0, 3);
		world.setBlock(x + 2, y + 2, z + 16, Blocks.air, 0, 3);
		world.setBlock(x + 3, y + 2, z + 16, Blocks.air, 0, 3);
		world.setBlock(x + 4, y + 2, z + 16, Blocks.air, 0, 3);
		world.setBlock(x + 5, y + 2, z + 16, Blocks.air, 0, 3);
		world.setBlock(x + 7, y + 2, z + 16, Blocks.stone_pressure_plate, 0, 3);
		world.setBlock(x + 9, y + 2, z + 16, Blocks.air, 0, 3);
		world.setBlock(x + 10, y + 2, z + 16, Blocks.air, 0, 3);
		world.setBlock(x + 11, y + 2, z + 16, Blocks.air, 0, 3);
		world.setBlock(x + 12, y + 2, z + 16, Blocks.air, 0, 3);
		world.setBlock(x + 13, y + 2, z + 16, Blocks.air, 0, 3);
		world.setBlock(x + 14, y + 2, z + 16, Blocks.air, 0, 3);
		world.setBlock(x + 15, y + 2, z + 16, Blocks.air, 0, 3);
		world.setBlock(x + 16, y + 2, z + 16, Blocks.air, 0, 3);
		world.setBlock(x + 17, y + 2, z + 16, Blocks.air, 0, 3);
		world.setBlock(x + 18, y + 2, z + 16, Blocks.air, 0, 3);
		world.setBlock(x + 19, y + 2, z + 16, Blocks.air, 0, 3);
		world.setBlock(x + 20, y + 2, z + 16, Blocks.air, 0, 3);
		world.setBlock(x + 21, y + 2, z + 16, Blocks.air, 0, 3);
		world.setBlock(x + 22, y + 2, z + 16, Blocks.glass, 0, 3);
		world.setBlock(x + 0, y + 2, z + 17, Blocks.stone, 0, 3);
		world.setBlock(x + 1, y + 2, z + 17, Blocks.stone, 0, 3);
		world.setBlock(x + 2, y + 2, z + 17, Blocks.stone, 0, 3);
		world.setBlock(x + 3, y + 2, z + 17, Blocks.stone, 0, 3);
		world.setBlock(x + 4, y + 2, z + 17, Blocks.stone, 0, 3);
		world.setBlock(x + 5, y + 2, z + 17, Blocks.glass, 0, 3);
		world.setBlock(x + 6, y + 2, z + 17, Blocks.glass, 0, 3);
		world.setBlock(x + 7, y + 2, z + 17, Blocks.glass, 0, 3);
		world.setBlock(x + 8, y + 2, z + 17, Blocks.stone, 0, 3);
		world.setBlock(x + 9, y + 2, z + 17, Blocks.wooden_door, 11, 3);
		world.setBlock(x + 10, y + 2, z + 17, Blocks.stone, 0, 3);
		world.setBlock(x + 11, y + 2, z + 17, Blocks.stone, 0, 3);
		world.setBlock(x + 12, y + 2, z + 17, Blocks.stone, 0, 3);
		world.setBlock(x + 13, y + 2, z + 17, Blocks.stone, 0, 3);
		world.setBlock(x + 14, y + 2, z + 17, Blocks.stone, 0, 3);
		world.setBlock(x + 15, y + 2, z + 17, Blocks.stone, 0, 3);
		world.setBlock(x + 16, y + 2, z + 17, Blocks.wooden_door, 11, 3);
		world.setBlock(x + 17, y + 2, z + 17, Blocks.wooden_door, 14, 3);
		world.setBlock(x + 18, y + 2, z + 17, Blocks.stone, 0, 3);
		world.setBlock(x + 19, y + 2, z + 17, Blocks.glass, 0, 3);
		world.setBlock(x + 20, y + 2, z + 17, Blocks.glass, 0, 3);
		world.setBlock(x + 21, y + 2, z + 17, Blocks.glass, 0, 3);
		world.setBlock(x + 22, y + 2, z + 17, Blocks.stone, 0, 3);
		world.setBlock(x + 0, y + 3, z + 0, Blocks.stone, 0, 3);
		world.setBlock(x + 1, y + 3, z + 0, Blocks.glass, 0, 3);
		world.setBlock(x + 2, y + 3, z + 0, Blocks.glass, 0, 3);
		world.setBlock(x + 3, y + 3, z + 0, Blocks.glass, 0, 3);
		world.setBlock(x + 4, y + 3, z + 0, Blocks.stone, 0, 3);
		world.setBlock(x + 5, y + 3, z + 0, Blocks.glass, 0, 3);
		world.setBlock(x + 6, y + 3, z + 0, Blocks.glass, 0, 3);
		world.setBlock(x + 7, y + 3, z + 0, Blocks.glass, 0, 3);
		world.setBlock(x + 8, y + 3, z + 0, Blocks.stone, 0, 3);
		world.setBlock(x + 10, y + 3, z + 0, Blocks.air, 0, 3);
		world.setBlock(x + 11, y + 3, z + 0, Blocks.air, 0, 3);
		world.setBlock(x + 12, y + 3, z + 0, Blocks.air, 0, 3);
		world.setBlock(x + 13, y + 3, z + 0, Blocks.air, 0, 3);
		world.setBlock(x + 14, y + 3, z + 0, Blocks.air, 0, 3);
		world.setBlock(x + 15, y + 3, z + 0, Blocks.air, 0, 3);
		world.setBlock(x + 16, y + 3, z + 0, Blocks.air, 0, 3);
		world.setBlock(x + 17, y + 3, z + 0, Blocks.air, 0, 3);
		world.setBlock(x + 18, y + 3, z + 0, Blocks.air, 0, 3);
		world.setBlock(x + 19, y + 3, z + 0, Blocks.air, 0, 3);
		world.setBlock(x + 20, y + 3, z + 0, Blocks.air, 0, 3);
		world.setBlock(x + 21, y + 3, z + 0, Blocks.air, 0, 3);
		world.setBlock(x + 22, y + 3, z + 0, Blocks.air, 0, 3);
		world.setBlock(x + 0, y + 3, z + 1, Blocks.glass, 0, 3);
		world.setBlock(x + 1, y + 3, z + 1, Blocks.air, 0, 3);
		world.setBlock(x + 2, y + 3, z + 1, Blocks.air, 0, 3);
		world.setBlock(x + 3, y + 3, z + 1, Blocks.air, 0, 3);
		world.setBlock(x + 5, y + 3, z + 1, Blocks.air, 0, 3);
		world.setBlock(x + 6, y + 3, z + 1, Blocks.air, 0, 3);
		world.setBlock(x + 7, y + 3, z + 1, Blocks.air, 0, 3);
		world.setBlock(x + 8, y + 3, z + 1, Blocks.glass, 0, 3);
		world.setBlock(x + 9, y + 3, z + 1, Blocks.air, 0, 3);
		world.setBlock(x + 10, y + 3, z + 1, Blocks.air, 0, 3);
		world.setBlock(x + 11, y + 3, z + 1, Blocks.air, 0, 3);
		world.setBlock(x + 12, y + 3, z + 1, Blocks.air, 0, 3);
		world.setBlock(x + 13, y + 3, z + 1, Blocks.air, 0, 3);
		world.setBlock(x + 14, y + 3, z + 1, Blocks.air, 0, 3);
		world.setBlock(x + 15, y + 3, z + 1, Blocks.air, 0, 3);
		world.setBlock(x + 16, y + 3, z + 1, Blocks.air, 0, 3);
		world.setBlock(x + 17, y + 3, z + 1, Blocks.air, 0, 3);
		world.setBlock(x + 18, y + 3, z + 1, Blocks.air, 0, 3);
		world.setBlock(x + 19, y + 3, z + 1, Blocks.air, 0, 3);
		world.setBlock(x + 20, y + 3, z + 1, Blocks.air, 0, 3);
		world.setBlock(x + 21, y + 3, z + 1, Blocks.air, 0, 3);
		world.setBlock(x + 22, y + 3, z + 1, Blocks.air, 0, 3);
		world.setBlock(x + 0, y + 3, z + 2, Blocks.glass, 0, 3);
		world.setBlock(x + 1, y + 3, z + 2, Blocks.air, 0, 3);
		world.setBlock(x + 2, y + 3, z + 2, Blocks.air, 0, 3);
		world.setBlock(x + 3, y + 3, z + 2, Blocks.air, 0, 3);
		world.setBlock(x + 4, y + 3, z + 2, Blocks.air, 0, 3);
		world.setBlock(x + 5, y + 3, z + 2, Blocks.air, 0, 3);
		world.setBlock(x + 6, y + 3, z + 2, Blocks.air, 0, 3);
		world.setBlock(x + 7, y + 3, z + 2, Blocks.air, 0, 3);
		world.setBlock(x + 8, y + 3, z + 2, Blocks.glass, 0, 3);
		world.setBlock(x + 9, y + 3, z + 2, Blocks.air, 0, 3);
		world.setBlock(x + 10, y + 3, z + 2, Blocks.air, 0, 3);
		world.setBlock(x + 11, y + 3, z + 2, Blocks.air, 0, 3);
		world.setBlock(x + 12, y + 3, z + 2, Blocks.air, 0, 3);
		world.setBlock(x + 13, y + 3, z + 2, Blocks.air, 0, 3);
		world.setBlock(x + 14, y + 3, z + 2, Blocks.air, 0, 3);
		world.setBlock(x + 15, y + 3, z + 2, Blocks.air, 0, 3);
		world.setBlock(x + 16, y + 3, z + 2, Blocks.air, 0, 3);
		world.setBlock(x + 17, y + 3, z + 2, Blocks.air, 0, 3);
		world.setBlock(x + 18, y + 3, z + 2, Blocks.air, 0, 3);
		world.setBlock(x + 19, y + 3, z + 2, Blocks.air, 0, 3);
		world.setBlock(x + 20, y + 3, z + 2, Blocks.air, 0, 3);
		world.setBlock(x + 21, y + 3, z + 2, Blocks.air, 0, 3);
		world.setBlock(x + 22, y + 3, z + 2, Blocks.air, 0, 3);
		world.setBlock(x + 0, y + 3, z + 3, Blocks.glass, 0, 3);
		world.setBlock(x + 1, y + 3, z + 3, Blocks.air, 0, 3);
		world.setBlock(x + 2, y + 3, z + 3, Blocks.air, 0, 3);
		world.setBlock(x + 3, y + 3, z + 3, Blocks.air, 0, 3);
		world.setBlock(x + 4, y + 3, z + 3, Blocks.air, 0, 3);
		world.setBlock(x + 5, y + 3, z + 3, Blocks.air, 0, 3);
		world.setBlock(x + 6, y + 3, z + 3, Blocks.air, 0, 3);
		world.setBlock(x + 8, y + 3, z + 3, Blocks.stone, 0, 3);
		world.setBlock(x + 10, y + 3, z + 3, Blocks.air, 0, 3);
		world.setBlock(x + 11, y + 3, z + 3, Blocks.air, 0, 3);
		world.setBlock(x + 12, y + 3, z + 3, Blocks.air, 0, 3);
		world.setBlock(x + 13, y + 3, z + 3, Blocks.air, 0, 3);
		world.setBlock(x + 14, y + 3, z + 3, Blocks.air, 0, 3);
		world.setBlock(x + 15, y + 3, z + 3, Blocks.air, 0, 3);
		world.setBlock(x + 16, y + 3, z + 3, Blocks.air, 0, 3);
		world.setBlock(x + 17, y + 3, z + 3, Blocks.air, 0, 3);
		world.setBlock(x + 18, y + 3, z + 3, Blocks.air, 0, 3);
		world.setBlock(x + 19, y + 3, z + 3, Blocks.air, 0, 3);
		world.setBlock(x + 20, y + 3, z + 3, Blocks.air, 0, 3);
		world.setBlock(x + 21, y + 3, z + 3, Blocks.air, 0, 3);
		world.setBlock(x + 22, y + 3, z + 3, Blocks.air, 0, 3);
		world.setBlock(x + 0, y + 3, z + 4, Blocks.stone, 0, 3);
		world.setBlock(x + 2, y + 3, z + 4, Blocks.air, 0, 3);
		world.setBlock(x + 3, y + 3, z + 4, Blocks.air, 0, 3);
		world.setBlock(x + 4, y + 3, z + 4, Blocks.air, 0, 3);
		world.setBlock(x + 5, y + 3, z + 4, Blocks.air, 0, 3);
		world.setBlock(x + 6, y + 3, z + 4, Blocks.air, 0, 3);
		world.setBlock(x + 7, y + 3, z + 4, Blocks.air, 0, 3);
		world.setBlock(x + 8, y + 3, z + 4, Blocks.stone, 0, 3);
		world.setBlock(x + 9, y + 3, z + 4, Blocks.air, 0, 3);
		world.setBlock(x + 10, y + 3, z + 4, Blocks.air, 0, 3);
		world.setBlock(x + 11, y + 3, z + 4, Blocks.air, 0, 3);
		world.setBlock(x + 12, y + 3, z + 4, Blocks.air, 0, 3);
		world.setBlock(x + 13, y + 3, z + 4, Blocks.air, 0, 3);
		world.setBlock(x + 14, y + 3, z + 4, Blocks.air, 0, 3);
		world.setBlock(x + 15, y + 3, z + 4, Blocks.air, 0, 3);
		world.setBlock(x + 16, y + 3, z + 4, Blocks.air, 0, 3);
		world.setBlock(x + 17, y + 3, z + 4, Blocks.air, 0, 3);
		world.setBlock(x + 18, y + 3, z + 4, Blocks.air, 0, 3);
		world.setBlock(x + 19, y + 3, z + 4, Blocks.air, 0, 3);
		world.setBlock(x + 20, y + 3, z + 4, Blocks.air, 0, 3);
		world.setBlock(x + 21, y + 3, z + 4, Blocks.air, 0, 3);
		world.setBlock(x + 22, y + 3, z + 4, Blocks.air, 0, 3);
		world.setBlock(x + 0, y + 3, z + 5, Blocks.glass, 0, 3);
		world.setBlock(x + 1, y + 3, z + 5, Blocks.air, 0, 3);
		world.setBlock(x + 2, y + 3, z + 5, Blocks.air, 0, 3);
		world.setBlock(x + 3, y + 3, z + 5, Blocks.air, 0, 3);
		world.setBlock(x + 4, y + 3, z + 5, Blocks.air, 0, 3);
		world.setBlock(x + 5, y + 3, z + 5, Blocks.air, 0, 3);
		world.setBlock(x + 6, y + 3, z + 5, Blocks.air, 0, 3);
		world.setBlock(x + 7, y + 3, z + 5, Blocks.air, 0, 3);
		world.setBlock(x + 8, y + 3, z + 5, Blocks.stone, 0, 3);
		world.setBlock(x + 9, y + 3, z + 5, Blocks.air, 0, 3);
		world.setBlock(x + 10, y + 3, z + 5, Blocks.air, 0, 3);
		world.setBlock(x + 11, y + 3, z + 5, Blocks.air, 0, 3);
		world.setBlock(x + 12, y + 3, z + 5, Blocks.air, 0, 3);
		world.setBlock(x + 13, y + 3, z + 5, Blocks.air, 0, 3);
		world.setBlock(x + 14, y + 3, z + 5, Blocks.air, 0, 3);
		world.setBlock(x + 15, y + 3, z + 5, Blocks.air, 0, 3);
		world.setBlock(x + 16, y + 3, z + 5, Blocks.air, 0, 3);
		world.setBlock(x + 17, y + 3, z + 5, Blocks.air, 0, 3);
		world.setBlock(x + 18, y + 3, z + 5, Blocks.air, 0, 3);
		world.setBlock(x + 19, y + 3, z + 5, Blocks.air, 0, 3);
		world.setBlock(x + 20, y + 3, z + 5, Blocks.air, 0, 3);
		world.setBlock(x + 21, y + 3, z + 5, Blocks.air, 0, 3);
		world.setBlock(x + 22, y + 3, z + 5, Blocks.air, 0, 3);
		world.setBlock(x + 0, y + 3, z + 6, Blocks.glass, 0, 3);
		world.setBlock(x + 1, y + 3, z + 6, Blocks.air, 0, 3);
		world.setBlock(x + 2, y + 3, z + 6, Blocks.air, 0, 3);
		world.setBlock(x + 3, y + 3, z + 6, Blocks.air, 0, 3);
		world.setBlock(x + 4, y + 3, z + 6, Blocks.air, 0, 3);
		world.setBlock(x + 5, y + 3, z + 6, Blocks.air, 0, 3);
		world.setBlock(x + 6, y + 3, z + 6, Blocks.air, 0, 3);
		world.setBlock(x + 8, y + 3, z + 6, Blocks.stone, 0, 3);
		world.setBlock(x + 10, y + 3, z + 6, Blocks.air, 0, 3);
		world.setBlock(x + 11, y + 3, z + 6, Blocks.air, 0, 3);
		world.setBlock(x + 12, y + 3, z + 6, Blocks.air, 0, 3);
		world.setBlock(x + 13, y + 3, z + 6, Blocks.air, 0, 3);
		world.setBlock(x + 14, y + 3, z + 6, Blocks.air, 0, 3);
		world.setBlock(x + 15, y + 3, z + 6, Blocks.air, 0, 3);
		world.setBlock(x + 17, y + 3, z + 6, Blocks.stone, 0, 3);
		world.setBlock(x + 18, y + 3, z + 6, Blocks.stone, 0, 3);
		world.setBlock(x + 19, y + 3, z + 6, Blocks.stone, 0, 3);
		world.setBlock(x + 20, y + 3, z + 6, Blocks.stone, 0, 3);
		world.setBlock(x + 21, y + 3, z + 6, Blocks.stone, 0, 3);
		world.setBlock(x + 22, y + 3, z + 6, Blocks.stone, 0, 3);
		world.setBlock(x + 0, y + 3, z + 7, Blocks.stone, 0, 3);
		world.setBlock(x + 2, y + 3, z + 7, Blocks.air, 0, 3);
		world.setBlock(x + 3, y + 3, z + 7, Blocks.air, 0, 3);
		world.setBlock(x + 4, y + 3, z + 7, Blocks.air, 0, 3);
		world.setBlock(x + 5, y + 3, z + 7, Blocks.air, 0, 3);
		world.setBlock(x + 6, y + 3, z + 7, Blocks.air, 0, 3);
		world.setBlock(x + 7, y + 3, z + 7, Blocks.air, 0, 3);
		world.setBlock(x + 8, y + 3, z + 7, Blocks.glass, 0, 3);
		world.setBlock(x + 9, y + 3, z + 7, Blocks.air, 0, 3);
		world.setBlock(x + 10, y + 3, z + 7, Blocks.air, 0, 3);
		world.setBlock(x + 11, y + 3, z + 7, Blocks.air, 0, 3);
		world.setBlock(x + 12, y + 3, z + 7, Blocks.air, 0, 3);
		world.setBlock(x + 13, y + 3, z + 7, Blocks.air, 0, 3);
		world.setBlock(x + 14, y + 3, z + 7, Blocks.air, 0, 3);
		world.setBlock(x + 15, y + 3, z + 7, Blocks.air, 0, 3);
		world.setBlock(x + 16, y + 3, z + 7, Blocks.air, 0, 3);
		world.setBlock(x + 17, y + 3, z + 7, Blocks.glass, 0, 3);
		world.setBlock(x + 19, y + 3, z + 7, Blocks.air, 0, 3);
		world.setBlock(x + 20, y + 3, z + 7, Blocks.air, 0, 3);
		world.setBlock(x + 22, y + 3, z + 7, Blocks.glass, 0, 3);
		world.setBlock(x + 0, y + 3, z + 8, Blocks.stone, 0, 3);
		world.setBlock(x + 1, y + 3, z + 8, Blocks.air, 0, 3);
		world.setBlock(x + 2, y + 3, z + 8, Blocks.air, 0, 3);
		world.setBlock(x + 3, y + 3, z + 8, Blocks.air, 0, 3);
		world.setBlock(x + 4, y + 3, z + 8, Blocks.air, 0, 3);
		world.setBlock(x + 5, y + 3, z + 8, Blocks.air, 0, 3);
		world.setBlock(x + 6, y + 3, z + 8, Blocks.air, 0, 3);
		world.setBlock(x + 7, y + 3, z + 8, Blocks.air, 0, 3);
		world.setBlock(x + 8, y + 3, z + 8, Blocks.glass, 0, 3);
		world.setBlock(x + 9, y + 3, z + 8, Blocks.air, 0, 3);
		world.setBlock(x + 10, y + 3, z + 8, Blocks.air, 0, 3);
		world.setBlock(x + 11, y + 3, z + 8, Blocks.air, 0, 3);
		world.setBlock(x + 12, y + 3, z + 8, Blocks.air, 0, 3);
		world.setBlock(x + 13, y + 3, z + 8, Blocks.air, 0, 3);
		world.setBlock(x + 14, y + 3, z + 8, Blocks.air, 0, 3);
		world.setBlock(x + 15, y + 3, z + 8, Blocks.air, 0, 3);
		world.setBlock(x + 16, y + 3, z + 8, Blocks.air, 0, 3);
		world.setBlock(x + 17, y + 3, z + 8, Blocks.glass, 0, 3);
		world.setBlock(x + 18, y + 3, z + 8, Blocks.air, 0, 3);
		world.setBlock(x + 19, y + 3, z + 8, Blocks.air, 0, 3);
		world.setBlock(x + 20, y + 3, z + 8, Blocks.air, 0, 3);
		world.setBlock(x + 21, y + 3, z + 8, Blocks.air, 0, 3);
		world.setBlock(x + 22, y + 3, z + 8, Blocks.glass, 0, 3);
		world.setBlock(x + 0, y + 3, z + 9, Blocks.stone, 0, 3);
		world.setBlock(x + 1, y + 3, z + 9, Blocks.air, 0, 3);
		world.setBlock(x + 2, y + 3, z + 9, Blocks.air, 0, 3);
		world.setBlock(x + 3, y + 3, z + 9, Blocks.air, 0, 3);
		world.setBlock(x + 4, y + 3, z + 9, Blocks.air, 0, 3);
		world.setBlock(x + 5, y + 3, z + 9, Blocks.air, 0, 3);
		world.setBlock(x + 6, y + 3, z + 9, Blocks.air, 0, 3);
		world.setBlock(x + 7, y + 3, z + 9, Blocks.air, 0, 3);
		world.setBlock(x + 8, y + 3, z + 9, Blocks.glass, 0, 3);
		world.setBlock(x + 9, y + 3, z + 9, Blocks.air, 0, 3);
		world.setBlock(x + 10, y + 3, z + 9, Blocks.air, 0, 3);
		world.setBlock(x + 12, y + 3, z + 9, Blocks.air, 0, 3);
		world.setBlock(x + 13, y + 3, z + 9, Blocks.air, 0, 3);
		world.setBlock(x + 15, y + 3, z + 9, Blocks.air, 0, 3);
		world.setBlock(x + 16, y + 3, z + 9, Blocks.air, 0, 3);
		world.setBlock(x + 17, y + 3, z + 9, Blocks.glass, 0, 3);
		world.setBlock(x + 18, y + 3, z + 9, Blocks.air, 0, 3);
		world.setBlock(x + 19, y + 3, z + 9, Blocks.air, 0, 3);
		world.setBlock(x + 20, y + 3, z + 9, Blocks.air, 0, 3);
		world.setBlock(x + 21, y + 3, z + 9, Blocks.air, 0, 3);
		world.setBlock(x + 22, y + 3, z + 9, Blocks.glass, 0, 3);
		world.setBlock(x + 0, y + 3, z + 10, Blocks.stone, 0, 3);
		world.setBlock(x + 2, y + 3, z + 10, Blocks.air, 0, 3);
		world.setBlock(x + 3, y + 3, z + 10, Blocks.air, 0, 3);
		world.setBlock(x + 4, y + 3, z + 10, Blocks.air, 0, 3);
		world.setBlock(x + 5, y + 3, z + 10, Blocks.air, 0, 3);
		world.setBlock(x + 6, y + 3, z + 10, Blocks.air, 0, 3);
		world.setBlock(x + 8, y + 3, z + 10, Blocks.stone, 0, 3);
		world.setBlock(x + 9, y + 3, z + 10, Blocks.glass, 0, 3);
		world.setBlock(x + 10, y + 3, z + 10, Blocks.glass, 0, 3);
		world.setBlock(x + 11, y + 3, z + 10, Blocks.stone, 0, 3);
		world.setBlock(x + 12, y + 3, z + 10, Blocks.stone, 0, 3);
		world.setBlock(x + 13, y + 3, z + 10, Blocks.stone, 0, 3);
		world.setBlock(x + 14, y + 3, z + 10, Blocks.stone, 0, 3);
		world.setBlock(x + 15, y + 3, z + 10, Blocks.glass, 0, 3);
		world.setBlock(x + 16, y + 3, z + 10, Blocks.glass, 0, 3);
		world.setBlock(x + 17, y + 3, z + 10, Blocks.stone, 0, 3);
		world.setBlock(x + 19, y + 3, z + 10, Blocks.air, 0, 3);
		world.setBlock(x + 20, y + 3, z + 10, Blocks.air, 0, 3);
		world.setBlock(x + 22, y + 3, z + 10, Blocks.stone, 0, 3);
		world.setBlock(x + 0, y + 3, z + 11, Blocks.glass, 0, 3);
		world.setBlock(x + 1, y + 3, z + 11, Blocks.air, 0, 3);
		world.setBlock(x + 2, y + 3, z + 11, Blocks.air, 0, 3);
		world.setBlock(x + 3, y + 3, z + 11, Blocks.air, 0, 3);
		world.setBlock(x + 4, y + 3, z + 11, Blocks.air, 0, 3);

		generate_r02(world, rand, x, y, z);
		return true;

	}
	public boolean generate_r02(World world, Random rand, int x, int y, int z)
	{

		world.setBlock(x + 5, y + 3, z + 11, Blocks.air, 0, 3);
		world.setBlock(x + 6, y + 3, z + 11, Blocks.air, 0, 3);
		world.setBlock(x + 7, y + 3, z + 11, Blocks.air, 0, 3);
		world.setBlock(x + 9, y + 3, z + 11, Blocks.air, 0, 3);
		world.setBlock(x + 10, y + 3, z + 11, Blocks.air, 0, 3);
		world.setBlock(x + 12, y + 3, z + 11, Blocks.air, 0, 3);
		world.setBlock(x + 13, y + 3, z + 11, Blocks.air, 0, 3);
		world.setBlock(x + 15, y + 3, z + 11, Blocks.air, 0, 3);
		world.setBlock(x + 16, y + 3, z + 11, Blocks.air, 0, 3);
		world.setBlock(x + 18, y + 3, z + 11, Blocks.air, 0, 3);
		world.setBlock(x + 19, y + 3, z + 11, Blocks.air, 0, 3);
		world.setBlock(x + 20, y + 3, z + 11, Blocks.air, 0, 3);
		world.setBlock(x + 21, y + 3, z + 11, Blocks.air, 0, 3);
		world.setBlock(x + 22, y + 3, z + 11, Blocks.glass, 0, 3);
		world.setBlock(x + 0, y + 3, z + 12, Blocks.glass, 0, 3);
		world.setBlock(x + 1, y + 3, z + 12, Blocks.air, 0, 3);
		world.setBlock(x + 2, y + 3, z + 12, Blocks.air, 0, 3);
		world.setBlock(x + 3, y + 3, z + 12, Blocks.air, 0, 3);
		world.setBlock(x + 4, y + 3, z + 12, Blocks.air, 0, 3);
		world.setBlock(x + 5, y + 3, z + 12, Blocks.air, 0, 3);
		world.setBlock(x + 6, y + 3, z + 12, Blocks.air, 0, 3);
		world.setBlock(x + 7, y + 3, z + 12, Blocks.air, 0, 3);
		world.setBlock(x + 8, y + 3, z + 12, Blocks.air, 0, 3);
		world.setBlock(x + 9, y + 3, z + 12, Blocks.air, 0, 3);
		world.setBlock(x + 10, y + 3, z + 12, Blocks.air, 0, 3);
		world.setBlock(x + 11, y + 3, z + 12, Blocks.air, 0, 3);
		world.setBlock(x + 12, y + 3, z + 12, Blocks.air, 0, 3);
		world.setBlock(x + 13, y + 3, z + 12, Blocks.air, 0, 3);
		world.setBlock(x + 14, y + 3, z + 12, Blocks.air, 0, 3);
		world.setBlock(x + 15, y + 3, z + 12, Blocks.air, 0, 3);
		world.setBlock(x + 16, y + 3, z + 12, Blocks.air, 0, 3);
		world.setBlock(x + 17, y + 3, z + 12, Blocks.air, 0, 3);
		world.setBlock(x + 18, y + 3, z + 12, Blocks.air, 0, 3);
		world.setBlock(x + 19, y + 3, z + 12, Blocks.air, 0, 3);
		world.setBlock(x + 20, y + 3, z + 12, Blocks.air, 0, 3);
		world.setBlock(x + 21, y + 3, z + 12, Blocks.air, 0, 3);
		world.setBlock(x + 22, y + 3, z + 12, Blocks.glass, 0, 3);
		world.setBlock(x + 0, y + 3, z + 13, Blocks.stone, 0, 3);
		world.setBlock(x + 2, y + 3, z + 13, Blocks.air, 0, 3);
		world.setBlock(x + 3, y + 3, z + 13, Blocks.air, 0, 3);
		world.setBlock(x + 4, y + 3, z + 13, Blocks.air, 0, 3);
		world.setBlock(x + 5, y + 3, z + 13, Blocks.air, 0, 3);
		world.setBlock(x + 6, y + 3, z + 13, Blocks.air, 0, 3);
		world.setBlock(x + 7, y + 3, z + 13, Blocks.air, 0, 3);
		world.setBlock(x + 8, y + 3, z + 13, Blocks.air, 0, 3);
		world.setBlock(x + 9, y + 3, z + 13, Blocks.air, 0, 3);
		world.setBlock(x + 10, y + 3, z + 13, Blocks.air, 0, 3);
		world.setBlock(x + 11, y + 3, z + 13, Blocks.air, 0, 3);
		world.setBlock(x + 12, y + 3, z + 13, Blocks.air, 0, 3);
		world.setBlock(x + 13, y + 3, z + 13, Blocks.air, 0, 3);
		world.setBlock(x + 14, y + 3, z + 13, Blocks.air, 0, 3);
		world.setBlock(x + 15, y + 3, z + 13, Blocks.air, 0, 3);
		world.setBlock(x + 16, y + 3, z + 13, Blocks.stone_stairs, 0, 3);
		world.setBlock(x + 17, y + 3, z + 13, Blocks.cobblestone, 0, 3);
		world.setBlock(x + 18, y + 3, z + 13, Blocks.cobblestone, 0, 3);
		world.setBlock(x + 19, y + 3, z + 13, Blocks.air, 0, 3);
		world.setBlock(x + 20, y + 3, z + 13, Blocks.air, 0, 3);
		world.setBlock(x + 22, y + 3, z + 13, Blocks.stone, 0, 3);
		world.setBlock(x + 0, y + 3, z + 14, Blocks.glass, 0, 3);
		world.setBlock(x + 1, y + 3, z + 14, Blocks.air, 0, 3);
		world.setBlock(x + 2, y + 3, z + 14, Blocks.air, 0, 3);
		world.setBlock(x + 3, y + 3, z + 14, Blocks.air, 0, 3);
		world.setBlock(x + 4, y + 3, z + 14, Blocks.air, 0, 3);
		world.setBlock(x + 5, y + 3, z + 14, Blocks.air, 0, 3);
		world.setBlock(x + 6, y + 3, z + 14, Blocks.air, 0, 3);
		world.setBlock(x + 7, y + 3, z + 14, Blocks.air, 0, 3);
		world.setBlock(x + 8, y + 3, z + 14, Blocks.air, 0, 3);
		world.setBlock(x + 9, y + 3, z + 14, Blocks.air, 0, 3);
		world.setBlock(x + 10, y + 3, z + 14, Blocks.air, 0, 3);
		world.setBlock(x + 11, y + 3, z + 14, Blocks.air, 0, 3);
		world.setBlock(x + 12, y + 3, z + 14, Blocks.air, 0, 3);
		world.setBlock(x + 13, y + 3, z + 14, Blocks.air, 0, 3);
		world.setBlock(x + 14, y + 3, z + 14, Blocks.air, 0, 3);
		world.setBlock(x + 15, y + 3, z + 14, Blocks.air, 0, 3);
		world.setBlock(x + 16, y + 3, z + 14, Blocks.stone_stairs, 0, 3);
		world.setBlock(x + 17, y + 3, z + 14, Blocks.cobblestone, 0, 3);
		world.setBlock(x + 18, y + 3, z + 14, Blocks.cobblestone, 0, 3);
		world.setBlock(x + 19, y + 3, z + 14, Blocks.air, 0, 3);
		world.setBlock(x + 20, y + 3, z + 14, Blocks.air, 0, 3);
		world.setBlock(x + 21, y + 3, z + 14, Blocks.air, 0, 3);
		world.setBlock(x + 22, y + 3, z + 14, Blocks.glass, 0, 3);
		world.setBlock(x + 0, y + 3, z + 15, Blocks.glass, 0, 3);
		world.setBlock(x + 1, y + 3, z + 15, Blocks.air, 0, 3);
		world.setBlock(x + 2, y + 3, z + 15, Blocks.air, 0, 3);
		world.setBlock(x + 3, y + 3, z + 15, Blocks.air, 0, 3);
		world.setBlock(x + 4, y + 3, z + 15, Blocks.air, 0, 3);
		world.setBlock(x + 5, y + 3, z + 15, Blocks.air, 0, 3);
		world.setBlock(x + 6, y + 3, z + 15, Blocks.air, 0, 3);
		world.setBlock(x + 7, y + 3, z + 15, Blocks.air, 0, 3);
		world.setBlock(x + 8, y + 3, z + 15, Blocks.air, 0, 3);
		world.setBlock(x + 9, y + 3, z + 15, Blocks.air, 0, 3);
		world.setBlock(x + 10, y + 3, z + 15, Blocks.air, 0, 3);
		world.setBlock(x + 11, y + 3, z + 15, Blocks.air, 0, 3);
		world.setBlock(x + 12, y + 3, z + 15, Blocks.air, 0, 3);
		world.setBlock(x + 13, y + 3, z + 15, Blocks.air, 0, 3);
		world.setBlock(x + 14, y + 3, z + 15, Blocks.air, 0, 3);
		world.setBlock(x + 15, y + 3, z + 15, Blocks.air, 0, 3);
		world.setBlock(x + 16, y + 3, z + 15, Blocks.air, 0, 3);
		world.setBlock(x + 17, y + 3, z + 15, Blocks.air, 0, 3);
		world.setBlock(x + 18, y + 3, z + 15, Blocks.air, 0, 3);
		world.setBlock(x + 19, y + 3, z + 15, Blocks.air, 0, 3);
		world.setBlock(x + 20, y + 3, z + 15, Blocks.air, 0, 3);
		world.setBlock(x + 21, y + 3, z + 15, Blocks.air, 0, 3);
		world.setBlock(x + 22, y + 3, z + 15, Blocks.glass, 0, 3);
		world.setBlock(x + 0, y + 3, z + 16, Blocks.glass, 0, 3);
		world.setBlock(x + 2, y + 3, z + 16, Blocks.air, 0, 3);
		world.setBlock(x + 3, y + 3, z + 16, Blocks.air, 0, 3);
		world.setBlock(x + 5, y + 3, z + 16, Blocks.air, 0, 3);
		world.setBlock(x + 6, y + 3, z + 16, Blocks.air, 0, 3);
		world.setBlock(x + 7, y + 3, z + 16, Blocks.air, 0, 3);
		world.setBlock(x + 9, y + 3, z + 16, Blocks.air, 0, 3);
		world.setBlock(x + 11, y + 3, z + 16, Blocks.air, 0, 3);
		world.setBlock(x + 12, y + 3, z + 16, Blocks.air, 0, 3);
		world.setBlock(x + 13, y + 3, z + 16, Blocks.air, 0, 3);
		world.setBlock(x + 14, y + 3, z + 16, Blocks.air, 0, 3);
		world.setBlock(x + 16, y + 3, z + 16, Blocks.air, 0, 3);
		world.setBlock(x + 17, y + 3, z + 16, Blocks.air, 0, 3);
		world.setBlock(x + 19, y + 3, z + 16, Blocks.air, 0, 3);
		world.setBlock(x + 20, y + 3, z + 16, Blocks.air, 0, 3);
		world.setBlock(x + 21, y + 3, z + 16, Blocks.air, 0, 3);
		world.setBlock(x + 22, y + 3, z + 16, Blocks.glass, 0, 3);
		world.setBlock(x + 0, y + 3, z + 17, Blocks.stone, 0, 3);
		world.setBlock(x + 1, y + 3, z + 17, Blocks.stone, 0, 3);
		world.setBlock(x + 2, y + 3, z + 17, Blocks.stone, 0, 3);
		world.setBlock(x + 3, y + 3, z + 17, Blocks.stone, 0, 3);
		world.setBlock(x + 4, y + 3, z + 17, Blocks.stone, 0, 3);
		world.setBlock(x + 5, y + 3, z + 17, Blocks.glass, 0, 3);
		world.setBlock(x + 6, y + 3, z + 17, Blocks.glass, 0, 3);
		world.setBlock(x + 7, y + 3, z + 17, Blocks.glass, 0, 3);
		world.setBlock(x + 8, y + 3, z + 17, Blocks.stone, 0, 3);
		world.setBlock(x + 9, y + 3, z + 17, Blocks.stone, 0, 3);
		world.setBlock(x + 10, y + 3, z + 17, Blocks.stone, 0, 3);
		world.setBlock(x + 11, y + 3, z + 17, Blocks.stone, 0, 3);
		world.setBlock(x + 12, y + 3, z + 17, Blocks.stone, 0, 3);
		world.setBlock(x + 13, y + 3, z + 17, Blocks.stone, 0, 3);
		world.setBlock(x + 14, y + 3, z + 17, Blocks.stone, 0, 3);
		world.setBlock(x + 15, y + 3, z + 17, Blocks.stone, 0, 3);
		world.setBlock(x + 16, y + 3, z + 17, Blocks.stone, 0, 3);
		world.setBlock(x + 17, y + 3, z + 17, Blocks.stone, 0, 3);
		world.setBlock(x + 18, y + 3, z + 17, Blocks.stone, 0, 3);
		world.setBlock(x + 19, y + 3, z + 17, Blocks.glass, 0, 3);
		world.setBlock(x + 20, y + 3, z + 17, Blocks.glass, 0, 3);
		world.setBlock(x + 21, y + 3, z + 17, Blocks.glass, 0, 3);
		world.setBlock(x + 22, y + 3, z + 17, Blocks.stone, 0, 3);
		world.setBlock(x + 0, y + 4, z + 0, Blocks.stone, 0, 3);
		world.setBlock(x + 1, y + 4, z + 0, Blocks.glass, 0, 3);
		world.setBlock(x + 2, y + 4, z + 0, Blocks.glass, 0, 3);
		world.setBlock(x + 3, y + 4, z + 0, Blocks.glass, 0, 3);
		world.setBlock(x + 4, y + 4, z + 0, Blocks.stone, 0, 3);
		world.setBlock(x + 5, y + 4, z + 0, Blocks.glass, 0, 3);
		world.setBlock(x + 6, y + 4, z + 0, Blocks.glass, 0, 3);
		world.setBlock(x + 7, y + 4, z + 0, Blocks.glass, 0, 3);
		world.setBlock(x + 8, y + 4, z + 0, Blocks.stone, 0, 3);
		world.setBlock(x + 9, y + 4, z + 0, Blocks.air, 0, 3);
		world.setBlock(x + 10, y + 4, z + 0, Blocks.air, 0, 3);
		world.setBlock(x + 11, y + 4, z + 0, Blocks.air, 0, 3);
		world.setBlock(x + 12, y + 4, z + 0, Blocks.air, 0, 3);
		world.setBlock(x + 13, y + 4, z + 0, Blocks.air, 0, 3);
		world.setBlock(x + 14, y + 4, z + 0, Blocks.air, 0, 3);
		world.setBlock(x + 15, y + 4, z + 0, Blocks.air, 0, 3);
		world.setBlock(x + 16, y + 4, z + 0, Blocks.air, 0, 3);
		world.setBlock(x + 17, y + 4, z + 0, Blocks.air, 0, 3);
		world.setBlock(x + 18, y + 4, z + 0, Blocks.air, 0, 3);
		world.setBlock(x + 19, y + 4, z + 0, Blocks.air, 0, 3);
		world.setBlock(x + 20, y + 4, z + 0, Blocks.air, 0, 3);
		world.setBlock(x + 21, y + 4, z + 0, Blocks.air, 0, 3);
		world.setBlock(x + 22, y + 4, z + 0, Blocks.air, 0, 3);
		world.setBlock(x + 0, y + 4, z + 1, Blocks.glass, 0, 3);
		world.setBlock(x + 1, y + 4, z + 1, Blocks.air, 0, 3);
		world.setBlock(x + 2, y + 4, z + 1, Blocks.air, 0, 3);
